Workbook

Sheet Notes
B1: To do
A5: PENDING | B5: Sensitivity/Scenario page
B6: Flip churn rate into Retention rate - Anwar to share the steep link.
A26: Anwar previous build notes - completed
A28: DONE | B28: Usability idea - autofeed all overheads onto one page so month end recs become faster
A29: DONE | B29: IT & ES - split out
A30: DONE | B30: Build a traffic % YoY change row in the D2C Model tabs
A31: KPIs | B31: Total number of subscriber base
A32: KPIs | B32: Total number of new customers
A33: DONE | B33: Need to think how we view in territory & function on same workflow
A34: DONE | B34: Need P&L Grouping (all functions) into EE, CE, UK and OTHER
A35: For fulfilment I would look at just using % assumptions on revenue same with COGs for CM1 but here is some revenue and overhead information that may help.
A37: B2B: Follow same phasing as this year
A38: Year 25/26 - £9.2m Minimal NPD - Growing what we have with some NPD -15% YOY
A39: Year 26/27 - 30% growth - £11.9m - New NPD and retail strategy in motion
A40: Year 27/28 - 30% Growth YOY - £15.5m
A42: Amazon: Follow same phasing as this year
A44: Year 25/26 - £3.5m - 15% Growth
A45: Year 26/27 - 30% growth - £4.55m - New NPD
A46: Year 27/28 - 30% Growth YOY - £5.9m
A48: DTC - Will use new DTC Model
A50: Overhead assumptions
A52: This year forecast is: £4.1m
... A58: Mainly driven by staff, office and relative increase to other overhead.

Sheet KPI Tracker
A1: KPI Tracker
A4: KPI | B4: 45689 | C4: 45717 | D4: 45748 | E4: 45778 | F4: 45809 | G4: 45839 | H4: 45870 | I4: 45901 | J4: 45931 | K4: 45962 | L4: 45992 | M4: 46023 | P4: Data source
A5: Total number of subscriber base | B5: 4640 | C5: 4492 | D5: 4668 | E5: 4562 | F5: 4204 | G5: 4481 | H5: 4274 | P5: https://web.steep.app/iJCBj22SsI2B/metrics/LM86etumQc29?chart=bar&from=2025-02-01&grain=auto&period=custom&tab=explore&to=2025-08-31
A6: of which adv+ | B6: 632 | C6: 579 | D6: 555 | E6: 549 | F6: 538 | G6: 753 | H6: 826 | P6: https://web.steep.app/iJCBj22SsI2B/metrics/LM86etumQc29?chart=bar&dim-8-kWIW2rwbcz=10-HB_PREMVIT&from=2025-02-01&grain=auto&period=custom&tab=explore&to=2025-08-31
A7: Total number of new customers | B7: 7369 | C7: 15233 | D7: 16122 | E7: 13374 | F7: 9633 | G7: 19530 | H7: 8210 | P7: https://web.steep.app/iJCBj22SsI2B/metrics/GOLeJLLE_shJ?chart=bar&from=2025-02-01&grain=auto&period=custom&tab=explore&to=2025-08-31
A12: Operating model | B12: FY25/26 | C12: FY25/26 | E12: FY26/27 | F12: FY26/27 | H12: FY27/28 | I12: FY27/28
B13: Ideal | C13: Forecast | E13: Ideal | F13: Forecast | H13: Ideal | I13: Forecast
A14: Sales | B14: 20.3 | C14: ='Combined P&L'!Q12/1000000 -> 18.027702 | E14: 27 | F14: ='Combined P&L'!AF12/1000000 -> 23.399235 | H14: 40.5 | I14: ='Combined P&L'!AU12/1000000 -> 34.315419
A16: COGS% | B16: 0.26 | C16: =C17/C14 -> 0.25921856 | E16: 0.26 | F16: =F17/F14 -> 0.24416794 | H16: 0.26 | I16: =I17/I14 -> 0.23657478
A17: COGS£ | B17: =B16*B14 -> 5.278 | C17: =-'Combined P&L'!Q21/1000000 -> 4.673115 | E17: =E16*E14 -> 7.02 | F17: =-'Combined P&L'!AF21/1000000 -> 5.7133429 | H17: =H16*H14 -> 10.53 | I17: =-'Combined P&L'!AU21/1000000 -> 8.1181627
A19: Ops & Fulfilment % | B19: 0.17 | C19: =C20/C14 -> 0.18898521 | E19: 0.17 | F19: =F20/F14 -> 0.17993976 | H19: 0.16 | I19: =I20/I14 -> 0.17174308
A20: Ops & Fulfilment £ | B20: =B19*B14 -> 3.451 | C20: =-'Combined P&L'!Q43/1000000 -> 3.406969 | E20: =E19*E14 -> 4.59 | F20: =-'Combined P&L'!AF43/1000000 -> 4.2104527 | H20: =H19*H14 -> 6.48 | I20: =-'Combined P&L'!AU43/1000000 -> 5.8934356
A22: Marketing % | B22: 0.28 | C22: =C23/C14 -> 0.29363193 | E22: 0.27 | F22: =F23/F14 -> 0.31740135 | H22: 0.27 | I22: =I23/I14 -> 0.2966971
A23: Marketing £ | B23: =B22*B14 -> 5.684 | C23: =-'Combined P&L'!Q71/1000000 -> 5.293509 | E23: =E22*E14 -> 7.29 | F23: =-'Combined P&L'!AF71/1000000 -> 7.4269488 | H23: =H22*H14 -> 10.935 | I23: =-'Combined P&L'!AU71/1000000 -> 10.181285
A25: Overhead % | B25: 0.2 | C25: =C27/C14 -> 0.22738603 | E25: 0.19 | F25: =F27/F14 -> 0.20693765 | H25: 0.18 | I25: =I27/I14 -> 0.16228031
A26: Of which people | B26: 0.147 | C26: =C28/C14 -> 0.15779454 | E26: 0.13 | F26: =F28/F14 -> 0.15035789 | H26: 0.11 | I26: =I28/I14 -> 0.10388373
A27: Overhead £ | B27: =B25*B14 -> 4.06 | C27: =-'Combined P&L'!Q99/1000000 -> 4.0992475 | E27: =E25*E14 -> 5.13 | F27: =-'Combined P&L'!AF99/1000000 -> 4.8421827 | H27: =H25*H14 -> 7.29 | I27: =-'Combined P&L'!AU99/1000000 -> 5.5687168
A28: Of which people £ | B28: =B26*B14 -> 2.9841 | C28: =-('Combined P&L'!Q89+'Combined P&L'!Q90)/1000000 -> 2.844673 | E28: =E26*E14 -> 3.51 | F28: =-('Combined P&L'!AF89+'Combined P&L'!AF90)/1000000 -> 3.5182596 | H28: =H26*H14 -> 4.455 | I28: =-('Combined P&L'!AU89+'Combined P&L'!AU90)/1000000 -> 3.5648137
A30: EBITDA % | B30: 0.09 | C30: =C31/C14 -> 0.030808373 | E30: 0.11 | F30: =F31/F14 -> 0.0061491279 | H30: 0.13 | I30: =I31/I14 -> 0.13270473
A31: EBITDA £M | B31: =B30*B14 -> 1.827 | C31: ='Combined P&L'!Q101/1000000 -> 0.55540417 | E31: =E30*E14 -> 2.97 | F31: ='Combined P&L'!T101/1000000 -> 0.14388489 | H31: =H30*H14 -> 5.265 | I31: ='Combined P&L'!AU101/1000000 -> 4.5538185

Sheet FY26-FY27 Summary
A2: Territory | B2: Revenue FY25/26 | C2: Revenue FY26/27 | D2: YoY % | F2: CM3 FY25/26 | G2: CM3% FY25/26 | H2: CM3 FY26/27 | I2: CM3% FY26/27 | J2: YoY %
A3: UK | B3: ='UK P&L'!Q12 -> 8107166.5 | C3: ='UK P&L'!AF12 -> 11362149 | D3: =(C3-B3)/B3 -> 0.40149452 | F3: ='UK P&L'!Q77 -> 1731349.6 | G3: ='UK P&L'!Q83 -> 0.21355792 | H3: ='UK P&L'!AF77 -> 2575624.8 | I3: ='UK P&L'!AF83 -> 0.22668464 | J3: =(H3-F3)/F3 -> 0.48763994
A4: CE | B4: ='CE P&L'!Q12 -> 3001838 | C4: ='CE P&L'!AF12 -> 4302007.5 | D4: =(C4-B4)/B4 -> 0.43312449 | F4: ='CE P&L'!Q77 -> 1051452.5 | G4: ='CE P&L'!Q83 -> 0.35026957 | H4: ='CE P&L'!AF77 -> 1261552 | I4: ='CE P&L'!AF83 -> 0.29324728 | J4: =(H4-F4)/F4 -> 0.19981835
A5: EE | B5: ='EE P&L'!Q12 -> 5593663 | C5: ='EE P&L'!AF12 -> 6840161.7 | D5: =(C5-B5)/B5 -> 0.22284122 | F5: ='EE P&L'!Q77 -> 1745507 | G5: ='EE P&L'!Q83 -> 0.3120508 | H5: ='EE P&L'!AF77 -> 2042799.9 | I5: ='EE P&L'!AF83 -> 0.29864789 | J5: =(H5-F5)/F5 -> 0.17031894
A6: ROW | B6: ='ROW P&L'!Q13 -> 1324326 | C6: ='ROW P&L'!AF13 -> 894916.07 | D6: =(C6-B6)/B6 -> -0.32424791 | F6: ='ROW P&L'!Q78 -> 614598 | G6: ='ROW P&L'!Q84 -> 0.46408362 | H6: ='ROW P&L'!AF78 -> 468513.56 | I6: ='ROW P&L'!AF84 -> 0.52352794 | J6: =(H6-F6)/F6 -> -0.23769104
A8: HU | B8: ='HU P&L'!Q12 -> 1566840.7 | C8: ='HU P&L'!AF12 -> 1837229.3 | D8: =(C8-B8)/B8 -> 0.17256931 | F8: ='HU P&L'!Q77 -> 477648.89 | G8: ='HU P&L'!Q83 -> 0.30484841 | H8: ='HU P&L'!AF77 -> 557044.66 | I8: ='HU P&L'!AF83 -> 0.30319823 | J8: =(H8-F8)/F8 -> 0.16622203
A9: IT | B9: ='IT P&L'!Q11 -> 953134.99 | C9: ='IT P&L'!AF11 -> 1367809.7 | D9: =(C9-B9)/B9 -> 0.43506395 | F9: ='IT P&L'!Q76 -> 327049.54 | G9: ='IT P&L'!Q82 -> 0.34313035 | H9: ='IT P&L'!AF76 -> 453219.16 | I9: ='IT P&L'!AF82 -> 0.33134666 | J9: =(H9-F9)/F9 -> 0.38578138
A10: SK | B10: ='SK P&L'!Q12 -> 1506094.1 | C10: ='SK P&L'!AF12 -> 1607823.1 | D10: =(C10-B10)/B10 -> 0.067544941 | F10: ='SK P&L'!Q77 -> 485906.66 | G10: ='SK P&L'!Q83 -> 0.32262703 | H10: ='SK P&L'!AF77 -> 525768.8 | I10: ='SK P&L'!AF83 -> 0.32700661 | J10: =(H10-F10)/F10 -> 0.082036616
A11: CZ | B11: ='CZ P&L'!Q11 -> 1663108.5 | C11: ='CZ P&L'!AF11 -> 2218111.4 | D11: =(C11-B11)/B11 -> 0.33371422 | F11: ='CZ P&L'!Q75 -> 578894.26 | G11: ='CZ P&L'!Q81 -> 0.34807968 | H11: ='CZ P&L'!AF75 -> 777869.53 | I11: ='CZ P&L'!AF81 -> 0.35069002 | J11: =(H11-F11)/F11 -> 0.3437161
A12: RO | B12: ='RO P&L'!Q12 -> 857524.78 | C12: ='RO P&L'!AF12 -> 1068497.9 | D12: =(C12-B12)/B12 -> 0.24602563 | F12: ='RO P&L'!Q77 -> 201551.43 | G12: ='RO P&L'!Q83 -> 0.23503861 | H12: ='RO P&L'!AF77 -> 309885.62 | I12: ='RO P&L'!AF83 -> 0.29001988 | J12: =(H12-F12)/F12 -> 0.53750147
A13: ES | B13: ='ES P&L'!Q12 -> 1038036.3 | C13: ='ES P&L'!AF12 -> 1417747.9 | D13: =(C13-B13)/B13 -> 0.36579793 | F13: ='ES P&L'!Q77 -> 308059.29 | G13: ='ES P&L'!Q83 -> 0.29677121 | H13: ='ES P&L'!AF77 -> 328708.42 | I13: ='ES P&L'!AF83 -> 0.23185252 | J13: =(H13-F13)/F13 -> 0.067029716

Sheet Scenario
A1: P&L Scenario Planner | B1: FY27 | U1: FY28
B2: UK | E2: CE | H2: EE | K2: ROW | N2: Non Rev | Q2: Combined | U2: UK | X2: CE | AA2: EE | AD2: ROW | AG2: Non Rev | AJ2: Combined
B3: FY27 | C3: Change | D3: New | E3: FY27 | F3: Change | G3: New | H3: FY27 | I3: Change | J3: New | K3: FY27 | L3: Change | M3: New | N3: FY27 | O3: Change | P3: New | Q3: FY27 | R3: Change | S3: New | U3: FY28 | V3: Change | W3: New | X3: FY28 | Y3: Change | Z3: New | AA3: FY28 | AB3: Change | AC3: New | AD3: FY28 | AE3: Change | AF3: New | AG3: FY28 | AH3: Change | AI3: New | AJ3: FY28 | AK3: Change | AL3: New
A4: Revenue
A6: DTC Revenue | B6: ='UK P&L'!AF7 -> 4837985.8 | C6: 0 | D6: =B6+C6 -> 4837985.8 | E6: ='CE P&L'!AF7 -> 1666198.3 | F6: 0 | G6: =E6+F6 -> 1666198.3 | H6: ='EE P&L'!AF7 -> 6022814.5 | I6: 0 | J6: =H6+I6 -> 6022814.5 | K6: ='ROW P&L'!AF8 -> 0 | L6: 0 | M6: =K6+L6 -> 0 | O6: 0 | P6: =N6+O6 -> 0 | Q6: =B6+E6+H6+K6+N6 -> 12526999 | R6: 0 | S6: =Q6+R6 -> 12526999 | U6: ='UK P&L'!AU7 -> 11107766 | V6: 0 | W6: =U6+V6 -> 11107766 | X6: ='CE P&L'!AU7 -> 3483235.2 | Y6: 0 | Z6: =X6+Y6 -> 3483235.2 | AA6: ='EE P&L'!AU7 -> 6936063.2 | AB6: 0 | AC6: =AA6+AB6 -> 6936063.2 | AD6: ='ROW P&L'!AU8 -> 0 | AE6: 0 | AF6: =AD6+AE6 -> 0 | AH6: 0 | AJ6: =U6+X6+AA6+AD6+AG6 -> 21527065 | AK6: 0 | AL6: =AJ6+AK6 -> 21527065
A7: B2B Revenue | B7: ='UK P&L'!AF8 -> 4178100.8 | C7: 0 | D7: =B7+C7 -> 4178100.8 | E7: ='CE P&L'!AF8 -> 1803733.2 | F7: 0 | G7: =E7+F7 -> 1803733.2 | H7: ='EE P&L'!AF8 -> 817347.16 | I7: 0 | J7: =H7+I7 -> 817347.16 | K7: ='ROW P&L'!AF9 -> 768617.31 | L7: 0 | M7: =K7+L7 -> 768617.31 | O7: 0 | P7: =N7+O7 -> 0 | Q7: =B7+E7+H7+K7+N7 -> 7567798.5 | R7: 0 | S7: =Q7+R7 -> 7567798.5 | U7: ='UK P&L'!AU8 -> 4971270.3 | V7: 0 | W7: =U7+V7 -> 4971270.3 | X7: ='CE P&L'!AU8 -> 2592839.9 | Y7: 0 | Z7: =X7+Y7 -> 2592839.9 | AA7: ='EE P&L'!AU8 -> 925414.52 | AB7: 0 | AC7: =AA7+AB7 -> 925414.52 | AD7: ='ROW P&L'!AU9 -> 795421.62 | AE7: 0 | AF7: =AD7+AE7 -> 795421.62 | AH7: 0 | AJ7: =U7+X7+AA7+AD7+AG7 -> 9284946.4 | AK7: 0 | AL7: =AJ7+AK7 -> 9284946.4
A8: Marketplace Revenue | B8: ='UK P&L'!AF9 -> 2346062.8 | C8: 0 | D8: =B8+C8 -> 2346062.8 | E8: ='CE P&L'!AF9 -> 832076.01 | F8: 0 | G8: =E8+F8 -> 832076.01 | H8: ='EE P&L'!AF9 -> 0 | I8: 0 | J8: =H8+I8 -> 0 | K8: ='ROW P&L'!AF10 -> 126298.76 | L8: 0 | M8: =K8+L8 -> 126298.76 | O8: 0 | P8: =N8+O8 -> 0 | Q8: =B8+E8+H8+K8+N8 -> 3304437.5 | R8: 0 | S8: =Q8+R8 -> 3304437.5 | U8: ='UK P&L'!AU9 -> 2369523.4 | V8: 0 | W8: =U8+V8 -> 2369523.4 | X8: ='CE P&L'!AU9 -> 1007585.8 | Y8: 0 | Z8: =X8+Y8 -> 1007585.8 | AA8: ='EE P&L'!AU9 -> 0 | AB8: 0 | AC8: =AA8+AB8 -> 0 | AD8: ='ROW P&L'!AU10 -> 126298.76 | AE8: 0 | AF8: =AD8+AE8 -> 126298.76 | AH8: 0 | AJ8: =U8+X8+AA8+AD8+AG8 -> 3503407.9 | AK8: 0 | AL8: =AJ8+AK8 -> 3503407.9
A9: TikTok Revenue | B9: ='UK P&L'!AF10 -> 0 | C9: 0 | D9: =B9+C9 -> 0 | E9: ='CE P&L'!AF10 -> 0 | F9: 0 | G9: =E9+F9 -> 0 | H9: ='EE P&L'!AF10 -> 0 | I9: 0 | J9: =H9+I9 -> 0 | K9: ='ROW P&L'!AF11 -> 0 | L9: 0 | M9: =K9+L9 -> 0 | O9: 0 | P9: =N9+O9 -> 0 | Q9: =B9+E9+H9+K9+N9 -> 0 | R9: 0 | S9: =Q9+R9 -> 0 | U9: ='UK P&L'!AU10 -> 0 | V9: 0 | W9: =U9+V9 -> 0 | X9: ='CE P&L'!AU10 -> 0 | Y9: 0 | Z9: =X9+Y9 -> 0 | AA9: ='EE P&L'!AU10 -> 0 | AB9: 0 | AC9: =AA9+AB9 -> 0 | AD9: ='ROW P&L'!AU11 -> 0 | AE9: 0 | AF9: =AD9+AE9 -> 0 | AH9: 0 | AJ9: =U9+X9+AA9+AD9+AG9 -> 0 | AK9: 0 | AL9: =AJ9+AK9 -> 0
A11: Total Revenue | B11: ='UK P&L'!AF12 -> 11362149 | C11: =SUM(C6:C9) -> 0 | D11: =B11+C11 -> 11362149 | E11: ='CE P&L'!AF12 -> 4302007.5 | F11: =SUM(F6:F9) -> 0 | G11: =E11+F11 -> 4302007.5 | H11: ='EE P&L'!AF12 -> 6840161.7 | I11: =SUM(I6:I9) -> 0 | J11: =H11+I11 -> 6840161.7 | K11: ='ROW P&L'!AF13 -> 894916.07 | L11: =SUM(L6:L9) -> 0 | M11: =K11+L11 -> 894916.07 | O11: =SUM(O6:O9) -> 0 | P11: =N11+O11 -> 0 | Q11: =B11+E11+H11+K11+N11 -> 23399235 | R11: =SUM(R6:R9) -> 0 | S11: =Q11+R11 -> 23399235 | U11: ='UK P&L'!AU12 -> 18448560 | V11: =SUM(V6:V9) -> 0 | W11: =U11+V11 -> 18448560 | X11: ='CE P&L'!AU12 -> 7083660.9 | Y11: =SUM(Y6:Y9) -> 0 | Z11: =X11+Y11 -> 7083660.9 | AA11: ='EE P&L'!AU12 -> 7861477.7 | AB11: =SUM(AB6:AB9) -> 0 | AC11: =AA11+AB11 -> 7861477.7 | AD11: ='ROW P&L'!AU13 -> 921720.38 | AE11: =SUM(AE6:AE9) -> 0 | AF11: =AD11+AE11 -> 921720.38 | AG11: ='Non Rev P&L'!AU7 -> 0 | AH11: =SUM(AH6:AH9) -> 0 | AI11: =AG11+AH11 -> 0 | AJ11: =U11+X11+AA11+AD11+AG11 -> 34315419 | AK11: =SUM(AK6:AK9) -> 0 | AL11: =AJ11+AK11 -> 34315419
A13: Cost of Goods Sold (CoGS)
A15: DTC CoGS | B15: ='UK P&L'!AF16 -> -1015977 | C15: 0 | D15: =B15+C15 -> -1015977 | E15: ='CE P&L'!AF16 -> -399887.59 | F15: 0 | G15: =E15+F15 -> -399887.59 | H15: ='EE P&L'!AF16 -> -1445475.5 | I15: 0 | J15: =H15+I15 -> -1445475.5 | K15: ='ROW P&L'!AF17 -> 0 | L15: 0 | M15: =K15+L15 -> 0 | O15: 0 | P15: =N15+O15 -> 0 | Q15: =B15+E15+H15+K15+N15 -> -2861340.1 | R15: 300000 | S15: =Q15+R15 -> -2561340.1 | U15: ='UK P&L'!AU16 -> -2221553.3 | V15: 0 | W15: =U15+V15 -> -2221553.3 | X15: ='CE P&L'!AU16 -> -835976.45 | Y15: 0 | Z15: =X15+Y15 -> -835976.45 | AA15: ='EE P&L'!AU16 -> -1664655.2 | AB15: 0 | AC15: =AA15+AB15 -> -1664655.2 | AD15: ='ROW P&L'!AU17 -> 0 | AE15: 0 | AF15: =AD15+AE15 -> 0 | AH15: 0 | AJ15: =U15+X15+AA15+AD15+AG15 -> -4722184.9 | AK15: 0 | AL15: =AJ15+AK15 -> -4722184.9
A16: B2B CoGS | B16: ='UK P&L'!AF17 -> -1066251.3 | C16: 0 | D16: =B16+C16 -> -1066251.3 | E16: ='CE P&L'!AF17 -> -577194.63 | F16: 0 | G16: =E16+F16 -> -577194.63 | H16: ='EE P&L'!AF17 -> -326938.87 | I16: 0 | J16: =H16+I16 -> -326938.87 | K16: ='ROW P&L'!AF18 -> -286819.27 | L16: 0 | M16: =K16+L16 -> -286819.27 | O16: 0 | P16: =N16+O16 -> 0 | Q16: =B16+E16+H16+K16+N16 -> -2257204.1 | R16: 0 | S16: =Q16+R16 -> -2257204.1 | U16: ='UK P&L'!AU17 -> -1268668.2 | V16: 0 | W16: =U16+V16 -> -1268668.2 | X16: ='CE P&L'!AU17 -> -829708.77 | Y16: 0 | Z16: =X16+Y16 -> -829708.77 | AA16: ='EE P&L'!AU17 -> -370165.81 | AB16: 0 | AC16: =AA16+AB16 -> -370165.81 | AD16: ='ROW P&L'!AU18 -> -296821.64 | AE16: 0 | AF16: =AD16+AE16 -> -296821.64 | AH16: 0 | AJ16: =U16+X16+AA16+AD16+AG16 -> -2765364.4 | AK16: 0 | AL16: =AJ16+AK16 -> -2765364.4
A17: Marketplace CoGS | B17: ='UK P&L'!AF18 -> -422291.3 | C17: 0 | D17: =B17+C17 -> -422291.3 | E17: ='CE P&L'!AF18 -> -149773.68 | F17: 0 | G17: =E17+F17 -> -149773.68 | H17: ='EE P&L'!AF18 -> 0 | I17: 0 | J17: =H17+I17 -> 0 | K17: ='ROW P&L'!AF19 -> -22733.777 | L17: 0 | M17: =K17+L17 -> -22733.777 | O17: 0 | P17: =N17+O17 -> 0 | Q17: =B17+E17+H17+K17+N17 -> -594798.76 | R17: 0 | S17: =Q17+R17 -> -594798.76 | U17: ='UK P&L'!AU18 -> -426514.21 | V17: 0 | W17: =U17+V17 -> -426514.21 | X17: ='CE P&L'!AU18 -> -181365.44 | Y17: 0 | Z17: =X17+Y17 -> -181365.44 | AA17: ='EE P&L'!AU18 -> 0 | AB17: 0 | AC17: =AA17+AB17 -> 0 | AD17: ='ROW P&L'!AU19 -> -22733.777 | AE17: 0 | AF17: =AD17+AE17 -> -22733.777 | AH17: 0 | AJ17: =U17+X17+AA17+AD17+AG17 -> -630613.43 | AK17: 0 | AL17: =AJ17+AK17 -> -630613.43
A18: TikTok CoGS | B18: ='UK P&L'!AF19 -> 0 | C18: 0 | D18: =B18+C18 -> 0 | E18: ='CE P&L'!AF19 -> 0 | F18: 0 | G18: =E18+F18 -> 0 | H18: ='EE P&L'!AF19 -> 0 | I18: 0 | J18: =H18+I18 -> 0 | K18: ='ROW P&L'!AF20 -> 0 | L18: 0 | M18: =K18+L18 -> 0 | O18: 0 | P18: =N18+O18 -> 0 | Q18: =B18+E18+H18+K18+N18 -> 0 | R18: 0 | S18: =Q18+R18 -> 0 | U18: ='UK P&L'!AU19 -> 0 | V18: 0 | W18: =U18+V18 -> 0 | X18: ='CE P&L'!AU19 -> 0 | Y18: 0 | Z18: =X18+Y18 -> 0 | AA18: ='EE P&L'!AU19 -> 0 | AB18: 0 | AC18: =AA18+AB18 -> 0 | AD18: ='ROW P&L'!AU20 -> 0 | AE18: 0 | AF18: =AD18+AE18 -> 0 | AH18: 0 | AJ18: =U18+X18+AA18+AD18+AG18 -> 0 | AK18: 0 | AL18: =AJ18+AK18 -> 0
A20: Total CoGS | B20: ='UK P&L'!AF21 -> -2504519.6 | C20: =SUM(C15:C18) -> 0 | D20: =B20+C20 -> -2504519.6 | E20: ='CE P&L'!AF21 -> -1126855.9 | F20: =SUM(F15:F18) -> 0 | G20: =E20+F20 -> -1126855.9 | H20: ='EE P&L'!AF21 -> -1772414.3 | I20: =SUM(I15:I18) -> 0 | J20: =H20+I20 -> -1772414.3 | K20: ='ROW P&L'!AF22 -> -309553.05 | L20: =SUM(L15:L18) -> 0 | M20: =K20+L20 -> -309553.05 | N20: ='Non Rev P&L'!AF12 -> 0 | O20: =SUM(O15:O18) -> 0 | P20: =N20+O20 -> 0 | Q20: =B20+E20+H20+K20+N20 -> -5713342.9 | R20: =SUM(R15:R18) -> 300000 | S20: =Q20+R20 -> -5413342.9 | U20: ='UK P&L'!AU21 -> -3916735.7 | V20: =SUM(V15:V18) -> 0 | W20: =U20+V20 -> -3916735.7 | X20: ='CE P&L'!AU21 -> -1847050.7 | Y20: =SUM(Y15:Y18) -> 0 | Z20: =X20+Y20 -> -1847050.7 | AA20: ='EE P&L'!AU21 -> -2034821 | AB20: =SUM(AB15:AB18) -> 0 | AC20: =AA20+AB20 -> -2034821 | AD20: ='ROW P&L'!AU22 -> -319555.41 | AE20: =SUM(AE15:AE18) -> 0 | AF20: =AD20+AE20 -> -319555.41 | AG20: ='Non Rev P&L'!AU12 -> 0 | AH20: =SUM(AH15:AH18) -> 0 | AI20: =AG20+AH20 -> 0 | AJ20: =U20+X20+AA20+AD20+AG20 -> -8118162.7 | AK20: =SUM(AK15:AK18) -> 0 | AL20: =AJ20+AK20 -> -8118162.7
A22: DTC CM1 | B22: ='UK P&L'!AF23 -> 3822008.8 | E22: ='UK P&L'!AI23 -> 554524.82 | H22: ='UK P&L'!AL23 -> 667945.7 | K22: ='UK P&L'!AO23 -> 780594.42 | N22: ='UK P&L'!AR23 -> 908294.21 | Q22: ='UK P&L'!AU23 -> 8886213 | U22: ='UK P&L'!AY23 -> 0 | X22: ='UK P&L'!BB23 -> 0 | AA22: ='UK P&L'!BE23 -> 0 | AD22: ='UK P&L'!BH23 -> 0 | AG22: ='UK P&L'!BK23 -> 0 | AJ22: ='UK P&L'!BN23 -> 0
A23: B2B CM1 | B23: ='UK P&L'!AF24 -> 3111849.5 | E23: ='UK P&L'!AI24 -> 225085.8 | H23: ='UK P&L'!AL24 -> 262000.55 | K23: ='UK P&L'!AO24 -> 726888.5 | N23: ='UK P&L'!AR24 -> 295527.84 | Q23: ='UK P&L'!AU24 -> 3702602.1 | U23: ='UK P&L'!AY24 -> 0 | X23: ='UK P&L'!BB24 -> 0 | AA23: ='UK P&L'!BE24 -> 0 | AD23: ='UK P&L'!BH24 -> 0 | AG23: ='UK P&L'!BK24 -> 0 | AJ23: ='UK P&L'!BN24 -> 0
A24: Marketplace CM1 | B24: ='UK P&L'!AF25 -> 1923771.5 | E24: ='UK P&L'!AI25 -> 157016.78 | H24: ='UK P&L'!AL25 -> 149512.67 | K24: ='UK P&L'!AO25 -> 160613.71 | N24: ='UK P&L'!AR25 -> 191028.94 | Q24: ='UK P&L'!AU25 -> 1943009.2 | U24: ='UK P&L'!AY25 -> 0 | X24: ='UK P&L'!BB25 -> 0 | AA24: ='UK P&L'!BE25 -> 0 | AD24: ='UK P&L'!BH25 -> 0 | AG24: ='UK P&L'!BK25 -> 0 | AJ24: ='UK P&L'!BN25 -> 0
A25: TikTok CM1 | B25: ='UK P&L'!AF26 -> 0 | E25: ='UK P&L'!AI26 -> 0 | H25: ='UK P&L'!AL26 -> 0 | K25: ='UK P&L'!AO26 -> 0 | N25: ='UK P&L'!AR26 -> 0 | Q25: ='UK P&L'!AU26 -> 0 | U25: ='UK P&L'!AY26 -> 0 | X25: ='UK P&L'!BB26 -> 0 | AA25: ='UK P&L'!BE26 -> 0 | AD25: ='UK P&L'!BH26 -> 0 | AG25: ='UK P&L'!BK26 -> 0 | AJ25: ='UK P&L'!BN26 -> 0
A26: Total CM1 | B26: ='UK P&L'!AF27 -> 8857629.8 | E26: ='UK P&L'!AI27 -> 936627.41 | H26: ='UK P&L'!AL27 -> 1079458.9 | K26: ='UK P&L'!AO27 -> 1668096.6 | N26: ='UK P&L'!AR27 -> 1394851 | Q26: ='UK P&L'!AU27 -> 14531824 | U26: ='UK P&L'!AY27 -> 0 | X26: ='UK P&L'!BB27 -> 0 | AA26: ='UK P&L'!BE27 -> 0 | AD26: ='UK P&L'!BH27 -> 0 | AG26: ='UK P&L'!BK27 -> 0 | AJ26: ='UK P&L'!BN27 -> 0
A28: DTC CM1% | B28: ='UK P&L'!AF29 -> 0.79 | E28: ='UK P&L'!AI29 -> 0.8 | H28: ='UK P&L'!AL29 -> 0.8 | K28: ='UK P&L'!AO29 -> 0.8 | N28: ='UK P&L'!AR29 -> 0.8 | Q28: ='UK P&L'!AU29 -> 0.8 | U28: ='UK P&L'!AY29 -> 0 | X28: ='UK P&L'!BB29 -> 0 | AA28: ='UK P&L'!BE29 -> 0 | AD28: ='UK P&L'!BH29 -> 0 | AG28: ='UK P&L'!BK29 -> 0 | AJ28: ='UK P&L'!BN29 -> 0
A29: B2B CM1% | B29: ='UK P&L'!AF30 -> 0.7448 | E29: ='UK P&L'!AI30 -> 0.7448 | H29: ='UK P&L'!AL30 -> 0.7448 | K29: ='UK P&L'!AO30 -> 0.7448 | N29: ='UK P&L'!AR30 -> 0.7448 | Q29: ='UK P&L'!AU30 -> 0.7448 | U29: ='UK P&L'!AY30 -> 0 | X29: ='UK P&L'!BB30 -> 0 | AA29: ='UK P&L'!BE30 -> 0 | AD29: ='UK P&L'!BH30 -> 0 | AG29: ='UK P&L'!BK30 -> 0 | AJ29: ='UK P&L'!BN30 -> 0
A30: Marketplace CM1% | B30: ='UK P&L'!AF31 -> 0.82 | E30: ='UK P&L'!AI31 -> 0.82 | H30: ='UK P&L'!AL31 -> 0.82 | K30: ='UK P&L'!AO31 -> 0.82 | N30: ='UK P&L'!AR31 -> 0.82 | Q30: ='UK P&L'!AU31 -> 0.82 | U30: ='UK P&L'!AY31 -> 0 | X30: ='UK P&L'!BB31 -> 0 | AA30: ='UK P&L'!BE31 -> 0 | AD30: ='UK P&L'!BH31 -> 0 | AG30: ='UK P&L'!BK31 -> 0 | AJ30: ='UK P&L'!BN31 -> 0
A31: TikTok CM1% | B31: ='UK P&L'!AF32 -> 0 | E31: ='UK P&L'!AI32 -> 0 | H31: ='UK P&L'!AL32 -> 0 | K31: ='UK P&L'!AO32 -> 0 | N31: ='UK P&L'!AR32 -> 0 | Q31: ='UK P&L'!AU32 -> 0 | U31: ='UK P&L'!AY32 -> 0 | X31: ='UK P&L'!BB32 -> 0 | AA31: ='UK P&L'!BE32 -> 0 | AD31: ='UK P&L'!BH32 -> 0 | AG31: ='UK P&L'!BK32 -> 0 | AJ31: ='UK P&L'!BN32 -> 0
A32: Total CM1% | B32: ='UK P&L'!AF33 -> 0.77957343 | E32: ='UK P&L'!AI33 -> 0.78917108 | H32: ='UK P&L'!AL33 -> 0.78848007 | K32: ='UK P&L'!AO33 -> 0.77673872 | N32: ='UK P&L'!AR33 -> 0.79023098 | Q32: ='UK P&L'!AU33 -> 0.78769423 | U32: ='UK P&L'!AY33 -> 0 | X32: ='UK P&L'!BB33 -> 0 | AA32: ='UK P&L'!BE33 -> 0 | AD32: ='UK P&L'!BH33 -> 0 | AG32: ='UK P&L'!BK33 -> 0 | AJ32: ='UK P&L'!BN33 -> 0
A34: Fulfilment
A36: Central | B36: ='UK P&L'!AF37 -> 0 | E36: ='CE P&L'!AF37 -> 0 | F36: 75000 | H36: ='EE P&L'!AF37 -> 0 | K36: ='ROW P&L'!AF38 -> 0 | N36: ='Non Rev P&L'!AF19 -> -300000 | O36: 0 | P36: =N36+O36 -> -300000 | Q36: =B36+E36+H36+K36+N36 -> -300000 | R36: 30000 | U36: ='UK P&L'!AU37 -> 0 | X36: ='CE P&L'!AU37 -> 0 | AA36: ='EE P&L'!AU37 -> 0 | AD36: ='ROW P&L'!AU38 -> 0 | AG36: ='Non Rev P&L'!AU19 -> -300000 | AJ36: =U36+X36+AA36+AD36+AG36 -> -300000 | AL36: =AJ36+AK36 -> -300000
A37: DTC Fulfilment | B37: ='UK P&L'!AF38 -> -660990.96 | C37: 0 | D37: =B37+C37 -> -660990.96 | E37: ='CE P&L'!AF38 -> -322094.41 | F37: 0 | G37: =E37+F37 -> -322094.41 | H37: ='EE P&L'!AF38 -> -1164276.1 | I37: 0 | J37: =H37+I37 -> -1164276.1 | K37: ='ROW P&L'!AF39 -> 0 | L37: 0 | M37: =K37+L37 -> 0 | N37: ='Non Rev P&L'!AF20 -> 0 | O37: 0 | P37: =N37+O37 -> 0 | Q37: =B37+E37+H37+K37+N37 -> -2147361.5 | R37: 0 | S37: =Q37+R37 -> -2147361.5 | U37: ='UK P&L'!AU38 -> -1517601.2 | V37: 0 | W37: =U37+V37 -> -1517601.2 | X37: ='CE P&L'!AU38 -> -673347.58 | Y37: 0 | Z37: =X37+Y37 -> -673347.58 | AA37: ='EE P&L'!AU38 -> -1340817.1 | AB37: 0 | AC37: =AA37+AB37 -> -1340817.1 | AD37: ='ROW P&L'!AU39 -> 0 | AE37: 0 | AF37: =AD37+AE37 -> 0 | AG37: ='Non Rev P&L'!AU20 -> 0 | AH37: 0 | AI37: =AG37+AH37 -> 0 | AJ37: =U37+X37+AA37+AD37+AG37 -> -3531765.9 | AK37: 0 | AL37: =AJ37+AK37 -> -3531765.9
A38: B2B Fulfilment | B38: ='UK P&L'!AF39 -> -217872.6 | C38: 0 | D38: =B38+C38 -> -217872.6 | E38: ='CE P&L'!AF39 -> -125712.74 | F38: 0 | G38: =E38+F38 -> -125712.74 | H38: ='EE P&L'!AF39 -> -49040.83 | I38: 0 | J38: =H38+I38 -> -49040.83 | K38: ='ROW P&L'!AF40 -> 0 | L38: 0 | M38: =K38+L38 -> 0 | N38: ='Non Rev P&L'!AF21 -> 0 | O38: 0 | P38: =N38+O38 -> 0 | Q38: =B38+E38+H38+K38+N38 -> -392626.17 | R38: 0 | S38: =Q38+R38 -> -392626.17 | U38: ='UK P&L'!AU39 -> -259233.47 | V38: 0 | W38: =U38+V38 -> -259233.47 | X38: ='CE P&L'!AU39 -> -180710.21 | Y38: 0 | Z38: =X38+Y38 -> -180710.21 | AA38: ='EE P&L'!AU39 -> -55524.871 | AB38: 0 | AC38: =AA38+AB38 -> -55524.871 | AD38: ='ROW P&L'!AU40 -> -110065.2 | AE38: 0 | AF38: =AD38+AE38 -> -110065.2 | AG38: ='Non Rev P&L'!AU21 -> 0 | AH38: 0 | AI38: =AG38+AH38 -> 0 | AJ38: =U38+X38+AA38+AD38+AG38 -> -605533.76 | AK38: 0 | AL38: =AJ38+AK38 -> -605533.76
A39: Marketplace Fulfilment | B39: ='UK P&L'!AF40 -> -955288.1 | C39: 0 | D39: =B39+C39 -> -955288.1 | E39: ='CE P&L'!AF40 -> -360868.49 | F39: 0 | G39: =E39+F39 -> -360868.49 | H39: ='EE P&L'!AF40 -> 0 | I39: 0 | J39: =H39+I39 -> 0 | K39: ='ROW P&L'!AF41 -> -54308.467 | L39: 0 | M39: =K39+L39 -> -54308.467 | N39: ='Non Rev P&L'!AF22 -> 0 | O39: 0 | P39: =N39+O39 -> 0 | Q39: =B39+E39+H39+K39+N39 -> -1370465.1 | R39: 0 | S39: =Q39+R39 -> -1370465.1 | U39: ='UK P&L'!AU40 -> -964840.99 | V39: 0 | W39: =U39+V39 -> -964840.99 | X39: ='CE P&L'!AU40 -> -436986.47 | Y39: 0 | Z39: =X39+Y39 -> -436986.47 | AA39: ='EE P&L'!AU40 -> 0 | AB39: 0 | AC39: =AA39+AB39 -> 0 | AD39: ='ROW P&L'!AU41 -> -54308.467 | AE39: 0 | AF39: =AD39+AE39 -> -54308.467 | AG39: ='Non Rev P&L'!AU22 -> 0 | AH39: 0 | AI39: =AG39+AH39 -> 0 | AJ39: =U39+X39+AA39+AD39+AG39 -> -1456135.9 | AK39: 0 | AL39: =AJ39+AK39 -> -1456135.9
A40: TikTok Fulfilment | B40: ='UK P&L'!AF41 -> 0 | C40: 0 | D40: =B40+C40 -> 0 | E40: ='CE P&L'!AF41 -> 0 | F40: 0 | G40: =E40+F40 -> 0 | H40: ='EE P&L'!AF41 -> 0 | I40: 0 | J40: =H40+I40 -> 0 | K40: ='ROW P&L'!AF42 -> 0 | L40: 0 | M40: =K40+L40 -> 0 | N40: ='Non Rev P&L'!AF23 -> 0 | O40: 0 | P40: =N40+O40 -> 0 | Q40: =B40+E40+H40+K40+N40 -> 0 | R40: 0 | S40: =Q40+R40 -> 0 | U40: ='UK P&L'!AU41 -> 0 | V40: 0 | W40: =U40+V40 -> 0 | X40: ='CE P&L'!AU41 -> 0 | Y40: 0 | Z40: =X40+Y40 -> 0 | AA40: ='EE P&L'!AU41 -> 0 | AB40: 0 | AC40: =AA40+AB40 -> 0 | AD40: ='ROW P&L'!AU42 -> 0 | AE40: 0 | AF40: =AD40+AE40 -> 0 | AG40: ='Non Rev P&L'!AU23 -> 0 | AH40: 0 | AI40: =AG40+AH40 -> 0 | AJ40: =U40+X40+AA40+AD40+AG40 -> 0 | AK40: 0 | AL40: =AJ40+AK40 -> 0
A42: Total Fulfilment | B42: ='UK P&L'!AF43 -> -1834151.7 | C42: =SUM(C36:C40) -> 0 | D42: =B42+C42 -> -1834151.7 | E42: ='CE P&L'!AF43 -> -808675.65 | F42: =SUM(F36:F40) -> 75000 | G42: =E42+F42 -> -733675.65 | H42: ='EE P&L'!AF43 -> -1213317 | I42: =SUM(I36:I40) -> 0 | J42: =H42+I42 -> -1213317 | K42: ='ROW P&L'!AF44 -> -54308.467 | L42: =SUM(L36:L40) -> 0 | M42: =K42+L42 -> -54308.467 | N42: ='Non Rev P&L'!AF24 -> -300000 | O42: =SUM(O36:O40) -> 0 | P42: =N42+O42 -> -300000 | Q42: =B42+E42+H42+K42+N42 -> -4210452.7 | R42: =SUM(R36:R40) -> 30000 | S42: =Q42+R42 -> -4180452.7 | U42: ='UK P&L'!AU43 -> -2741675.7 | V42: =SUM(V36:V40) -> 0 | W42: =U42+V42 -> -2741675.7 | X42: ='CE P&L'!AU43 -> -1291044.3 | Y42: =SUM(Y36:Y40) -> 0 | Z42: =X42+Y42 -> -1291044.3 | AA42: ='EE P&L'!AU43 -> -1396342 | AB42: =SUM(AB36:AB40) -> 0 | AC42: =AA42+AB42 -> -1396342 | AD42: ='ROW P&L'!AU44 -> -164373.67 | AE42: =SUM(AE36:AE40) -> 0 | AF42: =AD42+AE42 -> -164373.67 | AG42: ='Non Rev P&L'!AU24 -> -300000 | AH42: =SUM(AH36:AH40) -> 0 | AI42: =AG42+AH42 -> -300000 | AJ42: =U42+X42+AA42+AD42+AG42 -> -5893435.6 | AK42: =SUM(AK36:AK40) -> 0 | AL42: =AJ42+AK42 -> -5893435.6
A44: DTC CM2 | B44: ='UK P&L'!AF45 -> 3161017.8 | E44: ='UK P&L'!AI45 -> 459822.22 | H44: ='UK P&L'!AL45 -> 553872.9 | K44: ='UK P&L'!AO45 -> 647283.3 | N44: ='UK P&L'!AR45 -> 753174.32 | Q44: ='UK P&L'!AU45 -> 7368611.8 | U44: ='UK P&L'!AY45 -> 0 | X44: ='UK P&L'!BB45 -> 0 | AA44: ='UK P&L'!BE45 -> 0 | AD44: ='UK P&L'!BH45 -> 0 | AG44: ='UK P&L'!BK45 -> 0 | AJ44: ='UK P&L'!BN45 -> 0
A45: B2B CM2 | B45: ='UK P&L'!AF46 -> 2893976.9 | E45: ='UK P&L'!AI46 -> 209326.67 | H45: ='UK P&L'!AL46 -> 243656.88 | K45: ='UK P&L'!AO46 -> 675996.23 | N45: ='UK P&L'!AR46 -> 274836.79 | Q45: ='UK P&L'!AU46 -> 3443368.7 | U45: ='UK P&L'!AY46 -> 0 | X45: ='UK P&L'!BB46 -> 0 | AA45: ='UK P&L'!BE46 -> 0 | AD45: ='UK P&L'!BH46 -> 0 | AG45: ='UK P&L'!BK46 -> 0 | AJ45: ='UK P&L'!BN46 -> 0
A46: Marketplace CM2 | B46: ='UK P&L'!AF47 -> 968483.37 | E46: ='UK P&L'!AI47 -> 79046.885 | H46: ='UK P&L'!AL47 -> 75269.092 | K46: ='UK P&L'!AO47 -> 80857.686 | N46: ='UK P&L'!AR47 -> 96169.611 | Q46: ='UK P&L'!AU47 -> 978168.2 | U46: ='UK P&L'!AY47 -> 0 | X46: ='UK P&L'!BB47 -> 0 | AA46: ='UK P&L'!BE47 -> 0 | AD46: ='UK P&L'!BH47 -> 0 | AG46: ='UK P&L'!BK47 -> 0 | AJ46: ='UK P&L'!BN47 -> 0
A47: TikTok CM2 | B47: ='UK P&L'!AF48 -> 0 | E47: ='UK P&L'!AI48 -> 0 | H47: ='UK P&L'!AL48 -> 0 | K47: ='UK P&L'!AO48 -> 0 | N47: ='UK P&L'!AR48 -> 0 | Q47: ='UK P&L'!AU48 -> 0 | U47: ='UK P&L'!AY48 -> 0 | X47: ='UK P&L'!BB48 -> 0 | AA47: ='UK P&L'!BE48 -> 0 | AD47: ='UK P&L'!BH48 -> 0 | AG47: ='UK P&L'!BK48 -> 0 | AJ47: ='UK P&L'!BN48 -> 0
A48: Total CM2 | B48: ='UK P&L'!AF49 -> 7023478.1 | E48: ='UK P&L'!AI49 -> 748195.78 | H48: ='UK P&L'!AL49 -> 872798.88 | K48: ='UK P&L'!AO49 -> 1404137.2 | N48: ='UK P&L'!AR49 -> 1124180.7 | Q48: ='UK P&L'!AU49 -> 11790149 | U48: ='UK P&L'!AY49 -> 0 | X48: ='UK P&L'!BB49 -> 0 | AA48: ='UK P&L'!BE49 -> 0 | AD48: ='UK P&L'!BH49 -> 0 | AG48: ='UK P&L'!BK49 -> 0 | AJ48: ='UK P&L'!BN49 -> 0
A50: DTC CM2% | B50: ='UK P&L'!AF51 -> 0.65337476 | E50: ='UK P&L'!AI51 -> 0.66337476 | H50: ='UK P&L'!AL51 -> 0.66337476 | K50: ='UK P&L'!AO51 -> 0.66337476 | N50: ='UK P&L'!AR51 -> 0.66337476 | Q50: ='UK P&L'!AU51 -> 0.66337476 | U50: ='UK P&L'!AY51 -> 0 | X50: ='UK P&L'!BB51 -> 0 | AA50: ='UK P&L'!BE51 -> 0 | AD50: ='UK P&L'!BH51 -> 0 | AG50: ='UK P&L'!BK51 -> 0 | AJ50: ='UK P&L'!BN51 -> 0
A51: B2B CM2% | B51: ='UK P&L'!AF52 -> 0.69265368 | E51: ='UK P&L'!AI52 -> 0.69265368 | H51: ='UK P&L'!AL52 -> 0.69265368 | K51: ='UK P&L'!AO52 -> 0.69265368 | N51: ='UK P&L'!AR52 -> 0.69265368 | Q51: ='UK P&L'!AU52 -> 0.69265368 | U51: ='UK P&L'!AY52 -> 0 | X51: ='UK P&L'!BB52 -> 0 | AA51: ='UK P&L'!BE52 -> 0 | AD51: ='UK P&L'!BH52 -> 0 | AG51: ='UK P&L'!BK52 -> 0 | AJ51: ='UK P&L'!BN52 -> 0
A52: Marketplace CM2% | B52: ='UK P&L'!AF53 -> 0.41281221 | E52: ='UK P&L'!AI53 -> 0.41281221 | H52: ='UK P&L'!AL53 -> 0.41281221 | K52: ='UK P&L'!AO53 -> 0.41281221 | N52: ='UK P&L'!AR53 -> 0.41281221 | Q52: ='UK P&L'!AU53 -> 0.41281221 | U52: ='UK P&L'!AY53 -> 0 | X52: ='UK P&L'!BB53 -> 0 | AA52: ='UK P&L'!BE53 -> 0 | AD52: ='UK P&L'!BH53 -> 0 | AG52: ='UK P&L'!BK53 -> 0 | AJ52: ='UK P&L'!BN53 -> 0
...

Sheet YoY Comp
A1: YoY Comp
B2: FY26 (Current Year) | I2: FY26/27 | P2: YoY Comparison 26/27 | W2: FY28 | AD2: YoY Comparison 27/28 | AK2: FY27 Stretch | AR2: YoY Comparison 26/27 Stretch | AY2: FY28 Stretch | BF2: YoY Comparison 27/28 Stretch
B3: UK | C3: CE | D3: EE | E3: ROW | F3: Non Rev | G3: Combined | I3: UK | J3: CE | K3: EE | L3: ROW | M3: Non Rev | N3: Combined | P3: UK | Q3: CE | R3: EE | S3: ROW | T3: Non Rev | U3: Combined | W3: UK | X3: CE | Y3: EE | Z3: ROW | AA3: Non Rev | AB3: Combined | AD3: UK | AE3: CE | AF3: EE | AG3: ROW | AH3: Non Rev | AI3: Combined | AK3: UK | AL3: CE | AM3: EE | AN3: ROW | AO3: Non Rev | AP3: Combined | AR3: UK | AS3: CE | AT3: EE | AU3: ROW | AV3: Non Rev | AW3: Combined | AY3: UK | AZ3: CE | BA3: EE | BB3: ROW | BC3: Non Rev | BD3: Combined | BF3: UK | BG3: CE | BH3: EE | BI3: ROW | BJ3: Non Rev | BK3: Combined
A4: Revenue
A6: DTC Revenue | B6: 2202796 | C6: 1152910 | D6: 4950711 | E6: 46598 | G6: 8353015 | I6: 4837985.8 | J6: 1666198.3 | K6: 6022814.5 | L6: 0 | N6: 12526999 | P6: =IFERROR((I6-B6)/B6,0) -> 1.1962932 | Q6: =IFERROR((J6-C6)/C6,0) -> 0.44521108 | R6: =IFERROR((K6-D6)/D6,0) -> 0.21655546 | S6: =IFERROR((L6-E6)/E6,0) -> -1 | T6: =IFERROR((M6-F6)/F6,0) -> 0 | U6: =IFERROR((N6-G6)/G6,0) -> 0.49969785 | W6: 11107766 | X6: 3483235.2 | Y6: 6936063.2 | Z6: 0 | AB6: 21527065 | AD6: =IFERROR((W6-I6)/I6,0) -> 1.2959485 | AE6: =IFERROR((X6-J6)/J6,0) -> 1.0905286 | AF6: =IFERROR((Y6-K6)/K6,0) -> 0.15163155 | AG6: =IFERROR((Z6-L6)/L6,0) -> 0 | AH6: =IFERROR((AA6-M6)/M6,0) -> 0 | AI6: =IFERROR((AB6-N6)/N6,0) -> 0.7184535 | AK6: 5004917.5 | AL6: 2163434.5 | AM6: 6437527.6 | AN6: 0 | AP6: 13605880 | AR6: =IFERROR((AK6-B6)/B6,0) -> 1.2720749 | AS6: =IFERROR((AL6-C6)/C6,0) -> 0.87649904 | AT6: =IFERROR((AM6-D6)/D6,0) -> 0.30032385 | AU6: =IFERROR((AN6-E6)/E6,0) -> -1 | AV6: =IFERROR((AO6-F6)/F6,0) -> 0 | AW6: =IFERROR((AP6-G6)/G6,0) -> 0.62885851 | AY6: 11345162 | AZ6: 5147771.6 | BA6: 7466237.2 | BB6: 0 | BD6: 23959171 | BF6: =IFERROR((AY6-I6)/I6,0) -> 1.3450177 | BG6: =IFERROR((AZ6-J6)/J6,0) -> 2.0895311 | BH6: =IFERROR((BA6-K6)/K6,0) -> 0.23965916 | BI6: =IFERROR((BB6-L6)/L6,0) -> 0 | BJ6: =IFERROR((BC6-M6)/M6,0) -> 0 | BK6: =IFERROR((BD6-N6)/N6,0) -> 0.91260267
A7: B2B Revenue | B7: 3596822 | C7: 1243001 | D7: 642857 | E7: 1146191 | G7: 6628963 | I7: 4178100.8 | J7: 1803733.2 | K7: 817347.16 | L7: 768617.31 | N7: 7567798.5 | P7: =IFERROR((I7-B7)/B7,0) -> 0.161609 | Q7: =IFERROR((J7-C7)/C7,0) -> 0.45111164 | R7: =IFERROR((K7-D7)/D7,0) -> 0.2714292 | S7: =IFERROR((L7-E7)/E7,0) -> -0.32941603 | T7: =IFERROR((M7-F7)/F7,0) -> 0 | U7: =IFERROR((N7-G7)/G7,0) -> 0.1416263 | W7: 4971270.3 | X7: 2592839.9 | Y7: 925414.52 | Z7: 795421.62 | AB7: 9284946.4 | AD7: =IFERROR((W7-I7)/I7,0) -> 0.18983973 | AE7: =IFERROR((X7-J7)/J7,0) -> 0.43748525 | AF7: =IFERROR((Y7-K7)/K7,0) -> 0.13221721 | AG7: =IFERROR((Z7-L7)/L7,0) -> 0.034873418 | AH7: =IFERROR((AA7-M7)/M7,0) -> 0 | AI7: =IFERROR((AB7-N7)/N7,0) -> 0.2269019 | AK7: 4788173.5 | AL7: 2353893.3 | AM7: 840943.4 | AN7: 417314.65 | AP7: 8371647.6 | AR7: =IFERROR((AK7-B7)/B7,0) -> 0.33122337 | AS7: =IFERROR((AL7-C7)/C7,0) -> 0.89371791 | AT7: =IFERROR((AM7-D7)/D7,0) -> 0.30813446 | AU7: =IFERROR((AN7-E7)/E7,0) -> -0.63591177 | AV7: =IFERROR((AO7-F7)/F7,0) -> 0 | AW7: =IFERROR((AP7-G7)/G7,0) -> 0.26288947 | AY7: 4662436.2 | AZ7: 3911144 | BA7: 919490.57 | BB7: 1840320.6 | BD7: 10438438 | BF7: =IFERROR((AY7-I7)/I7,0) -> 0.11592238 | BG7: =IFERROR((AZ7-J7)/J7,0) -> 1.1683606 | BH7: =IFERROR((BA7-K7)/K7,0) -> 0.12496942 | BI7: =IFERROR((BB7-L7)/L7,0) -> 1.3943262 | BJ7: =IFERROR((BC7-M7)/M7,0) -> 0 | BK7: =IFERROR((BD7-N7)/N7,0) -> 0.37932296
A8: Marketplace Revenue | B8: 2217136 | C8: 605926 | E8: 131537 | G8: 2955853 | I8: 2346062.8 | J8: 832076.01 | K8: 0 | L8: 126298.76 | N8: 3304437.5 | P8: =IFERROR((I8-B8)/B8,0) -> 0.058150141 | Q8: =IFERROR((J8-C8)/C8,0) -> 0.37323042 | R8: =IFERROR((K8-D8)/D8,0) -> 0 | S8: =IFERROR((L8-E8)/E8,0) -> -0.03982332 | T8: =IFERROR((M8-F8)/F8,0) -> 0 | U8: =IFERROR((N8-G8)/G8,0) -> 0.11793027 | W8: 2369523.4 | X8: 1007585.8 | Y8: 0 | Z8: 126298.76 | AB8: 3503407.9 | AD8: =IFERROR((W8-I8)/I8,0) -> 0.01 | AE8: =IFERROR((X8-J8)/J8,0) -> 0.21092997 | AF8: =IFERROR((Y8-K8)/K8,0) -> 0 | AG8: =IFERROR((Z8-L8)/L8,0) -> 0 | AH8: =IFERROR((AA8-M8)/M8,0) -> 0 | AI8: =IFERROR((AB8-N8)/N8,0) -> 0.060213089 | AK8: 2551162 | AL8: 1334223.9 | AM8: 0 | AN8: 126298.76 | AP8: 4011684.7 | AR8: =IFERROR((AK8-B8)/B8,0) -> 0.15065652 | AS8: =IFERROR((AL8-C8)/C8,0) -> 1.2019585 | AT8: =IFERROR((AM8-D8)/D8,0) -> 0 | AU8: =IFERROR((AN8-E8)/E8,0) -> -0.03982332 | AV8: =IFERROR((AO8-F8)/F8,0) -> 0 | AW8: =IFERROR((AP8-G8)/G8,0) -> 0.35720033 | AY8: 2576673.6 | AZ8: 2339971.9 | BA8: 0 | BB8: 126298.76 | BD8: 5042944.2 | BF8: =IFERROR((AY8-I8)/I8,0) -> 0.098296965 | BG8: =IFERROR((AZ8-J8)/J8,0) -> 1.8122092 | BH8: =IFERROR((BA8-K8)/K8,0) -> 0 | BI8: =IFERROR((BB8-L8)/L8,0) -> 0 | BJ8: =IFERROR((BC8-M8)/M8,0) -> 0 | BK8: =IFERROR((BD8-N8)/N8,0) -> 0.52611274
A9: TikTok Revenue | B9: 89872 | G9: 89872 | I9: 0 | J9: 0 | K9: 0 | L9: 0 | N9: 0 | P9: =IFERROR((I9-B9)/B9,0) -> -1 | Q9: =IFERROR((J9-C9)/C9,0) -> 0 | R9: =IFERROR((K9-D9)/D9,0) -> 0 | S9: =IFERROR((L9-E9)/E9,0) -> 0 | T9: =IFERROR((M9-F9)/F9,0) -> 0 | U9: =IFERROR((N9-G9)/G9,0) -> -1 | W9: 0 | X9: 0 | Y9: 0 | Z9: 0 | AB9: 0 | AD9: =IFERROR((W9-I9)/I9,0) -> 0 | AE9: =IFERROR((X9-J9)/J9,0) -> 0 | AF9: =IFERROR((Y9-K9)/K9,0) -> 0 | AG9: =IFERROR((Z9-L9)/L9,0) -> 0 | AH9: =IFERROR((AA9-M9)/M9,0) -> 0 | AI9: =IFERROR((AB9-N9)/N9,0) -> 0 | AK9: 0 | AL9: 0 | AM9: 0 | AN9: 0 | AP9: 0 | AR9: =IFERROR((AK9-B9)/B9,0) -> -1 | AS9: =IFERROR((AL9-C9)/C9,0) -> 0 | AT9: =IFERROR((AM9-D9)/D9,0) -> 0 | AU9: =IFERROR((AN9-E9)/E9,0) -> 0 | AV9: =IFERROR((AO9-F9)/F9,0) -> 0 | AW9: =IFERROR((AP9-G9)/G9,0) -> -1 | AY9: 0 | AZ9: 0 | BA9: 0 | BB9: 0 | BD9: 0 | BF9: =IFERROR((AY9-I9)/I9,0) -> 0 | BG9: =IFERROR((AZ9-J9)/J9,0) -> 0 | BH9: =IFERROR((BA9-K9)/K9,0) -> 0 | BI9: =IFERROR((BB9-L9)/L9,0) -> 0 | BJ9: =IFERROR((BC9-M9)/M9,0) -> 0 | BK9: =IFERROR((BD9-N9)/N9,0) -> 0
A11: Total Revenue | B11: 8106625 | C11: 3001838 | D11: 5593568 | E11: 1324326 | G11: 18027702 | I11: 11362149 | J11: 4302007.5 | K11: 6840161.7 | L11: 894916.07 | M11: ='Non Rev P&L'!AF7 -> 0 | N11: 23399235 | P11: =IFERROR((I11-B11)/B11,0) -> 0.40158813 | Q11: =IFERROR((J11-C11)/C11,0) -> 0.43312449 | R11: =IFERROR((K11-D11)/D11,0) -> 0.22286199 | S11: =IFERROR((L11-E11)/E11,0) -> -0.32424791 | T11: =IFERROR((M11-F11)/F11,0) -> 0 | U11: =IFERROR((N11-G11)/G11,0) -> 0.29795992 | W11: 18448560 | X11: 7083660.9 | Y11: 7861477.7 | Z11: 921720.38 | AB11: 34315419 | AD11: =IFERROR((W11-I11)/I11,0) -> 0.62368575 | AE11: =IFERROR((X11-J11)/J11,0) -> 0.64659425 | AF11: =IFERROR((Y11-K11)/K11,0) -> 0.14931168 | AG11: =IFERROR((Z11-L11)/L11,0) -> 0.029951762 | AH11: =IFERROR((AA11-M11)/M11,0) -> 0 | AI11: =IFERROR((AB11-N11)/N11,0) -> 0.46651886 | AK11: 12344253 | AL11: 5851551.7 | AM11: 7278471 | AN11: 543613.41 | AP11: 25989212 | AR11: =IFERROR((AK11-B11)/B11,0) -> 0.52273641 | AS11: =IFERROR((AL11-C11)/C11,0) -> 0.94932294 | AT11: =IFERROR((AM11-D11)/D11,0) -> 0.3012215 | AU11: =IFERROR((AN11-E11)/E11,0) -> -0.58951692 | AV11: =IFERROR((AO11-F11)/F11,0) -> 0 | AW11: =IFERROR((AP11-G11)/G11,0) -> 0.44162644 | AY11: 18584272 | AZ11: 11398887 | BA11: 8385727.7 | BB11: 1966619.3 | BD11: 39440553 | BF11: =IFERROR((AY11-I11)/I11,0) -> 0.63562997 | BG11: =IFERROR((AZ11-J11)/J11,0) -> 1.649667 | BH11: =IFERROR((BA11-K11)/K11,0) -> 0.22595461 | BI11: =IFERROR((BB11-L11)/L11,0) -> 1.1975461 | BJ11: =IFERROR((BC11-M11)/M11,0) -> 0 | BK11: =IFERROR((BD11-N11)/N11,0) -> 0.68554887
A13: Cost of Goods Sold (CoGS)
A15: DTC CoGS | B15: -529860 | C15: -280038 | D15: -1269852 | E15: -6423 | F15: 26112 | G15: -2095277 | I15: -1015977 | J15: -399887.59 | K15: -1445475.5 | L15: 0 | N15: -2861340.1 | P15: =IFERROR((I15-B15)/B15,0) -> 0.91744428 | Q15: =IFERROR((J15-C15)/C15,0) -> 0.42797618 | R15: =IFERROR((K15-D15)/D15,0) -> 0.13830232 | S15: =IFERROR((L15-E15)/E15,0) -> -1 | T15: =IFERROR((M15-F15)/F15,0) -> -1 | U15: =IFERROR((N15-G15)/G15,0) -> 0.36561424 | W15: -2221553.3 | X15: -835976.45 | Y15: -1664655.2 | Z15: 0 | AB15: -4722184.9 | AD15: =IFERROR((W15-I15)/I15,0) -> 1.1866176 | AE15: =IFERROR((X15-J15)/J15,0) -> 1.0905286 | AF15: =IFERROR((Y15-K15)/K15,0) -> 0.15163155 | AG15: =IFERROR((Z15-L15)/L15,0) -> 0 | AH15: =IFERROR((AA15-M15)/M15,0) -> 0 | AI15: =IFERROR((AB15-N15)/N15,0) -> 0.6503403 | AK15: -1051032.7 | AL15: -519224.28 | AM15: -1545006.6 | AN15: 0 | AP15: -3115263.6 | AR15: =IFERROR((AK15-B15)/B15,0) -> 0.98360449 | AS15: =IFERROR((AL15-C15)/C15,0) -> 0.85412081 | AT15: =IFERROR((AM15-D15)/D15,0) -> 0.21668243 | AU15: =IFERROR((AN15-E15)/E15,0) -> -1 | AV15: =IFERROR((AO15-F15)/F15,0) -> -1 | AW15: =IFERROR((AP15-G15)/G15,0) -> 0.48680274 | AY15: -2269032.5 | AZ15: -1235465.2 | BA15: -1791896.9 | BB15: 0 | BD15: -5296394.6 | BF15: =IFERROR((AY15-I15)/I15,0) -> 1.2333502 | BG15: =IFERROR((AZ15-J15)/J15,0) -> 2.0895311 | BH15: =IFERROR((BA15-K15)/K15,0) -> 0.23965916 | BI15: =IFERROR((BB15-L15)/L15,0) -> 0 | BJ15: =IFERROR((BC15-M15)/M15,0) -> 0 | BK15: =IFERROR((BD15-N15)/N15,0) -> 0.85101888
A16: B2B CoGS | B16: -998660 | C16: -404020 | D16: -235555 | E16: -466664 | G16: -2053505 | I16: -1066251.3 | J16: -577194.63 | K16: -326938.87 | L16: -286819.27 | N16: -2257204.1 | P16: =IFERROR((I16-B16)/B16,0) -> 0.067682017 | Q16: =IFERROR((J16-C16)/C16,0) -> 0.42862886 | R16: =IFERROR((K16-D16)/D16,0) -> 0.38795129 | S16: =IFERROR((L16-E16)/E16,0) -> -0.38538377 | T16: =IFERROR((M16-F16)/F16,0) -> 0 | U16: =IFERROR((N16-G16)/G16,0) -> 0.099195809 | W16: -1268668.2 | X16: -829708.77 | Y16: -370165.81 | Z16: -296821.64 | AB16: -2765364.4 | AD16: =IFERROR((W16-I16)/I16,0) -> 0.18983973 | AE16: =IFERROR((X16-J16)/J16,0) -> 0.43748525 | AF16: =IFERROR((Y16-K16)/K16,0) -> 0.13221721 | AG16: =IFERROR((Z16-L16)/L16,0) -> 0.034873418 | AH16: =IFERROR((AA16-M16)/M16,0) -> 0 | AI16: =IFERROR((AB16-N16)/N16,0) -> 0.22512821 | AK16: -1221941.9 | AL16: -588473.31 | AM16: -252283.02 | AN16: -133540.69 | AP16: -2196238.9 | AR16: =IFERROR((AK16-B16)/B16,0) -> 0.22358148 | AS16: =IFERROR((AL16-C16)/C16,0) -> 0.45654501 | AT16: =IFERROR((AM16-D16)/D16,0) -> 0.071015341 | AU16: =IFERROR((AN16-E16)/E16,0) -> -0.71383975 | AV16: =IFERROR((AO16-F16)/F16,0) -> 0 | AW16: =IFERROR((AP16-G16)/G16,0) -> 0.069507454 | AY16: -1189853.7 | AZ16: -977786 | BA16: -275847.17 | BB16: -588902.59 | BD16: -3032389.5 | BF16: =IFERROR((AY16-I16)/I16,0) -> 0.11592238 | BG16: =IFERROR((AZ16-J16)/J16,0) -> 0.69403169 | BH16: =IFERROR((BA16-K16)/K16,0) -> -0.15627293 | BI16: =IFERROR((BB16-L16)/L16,0) -> 1.0532183 | BJ16: =IFERROR((BC16-M16)/M16,0) -> 0 | BK16: =IFERROR((BD16-N16)/N16,0) -> 0.34342724
A17: Marketplace CoGS | B17: -382302 | C17: -106836 | E17: -16207 | G17: -505343 | I17: -422291.3 | J17: -149773.68 | K17: 0 | L17: -22733.777 | N17: -594798.76 | P17: =IFERROR((I17-B17)/B17,0) -> 0.10460133 | Q17: =IFERROR((J17-C17)/C17,0) -> 0.40190275 | R17: =IFERROR((K17-D17)/D17,0) -> 0 | S17: =IFERROR((L17-E17)/E17,0) -> 0.40271344 | T17: =IFERROR((M17-F17)/F17,0) -> 0 | U17: =IFERROR((N17-G17)/G17,0) -> 0.17701988 | W17: -426514.21 | X17: -181365.44 | Y17: 0 | Z17: -22733.777 | AB17: -630613.43 | AD17: =IFERROR((W17-I17)/I17,0) -> 0.01 | AE17: =IFERROR((X17-J17)/J17,0) -> 0.21092997 | AF17: =IFERROR((Y17-K17)/K17,0) -> 0 | AG17: =IFERROR((Z17-L17)/L17,0) -> 0 | AH17: =IFERROR((AA17-M17)/M17,0) -> 0 | AI17: =IFERROR((AB17-N17)/N17,0) -> 0.060213089 | AK17: -459209.16 | AL17: -240160.31 | AM17: 0 | AN17: -22733.777 | AP17: -722103.24 | AR17: =IFERROR((AK17-B17)/B17,0) -> 0.2011686 | AS17: =IFERROR((AL17-C17)/C17,0) -> 1.2479343 | AT17: =IFERROR((AM17-D17)/D17,0) -> 0 | AU17: =IFERROR((AN17-E17)/E17,0) -> 0.40271344 | AV17: =IFERROR((AO17-F17)/F17,0) -> 0 | AW17: =IFERROR((AP17-G17)/G17,0) -> 0.42893687 | AY17: -463801.25 | AZ17: -421194.93 | BA17: 0 | BB17: -22733.777 | BD17: -907729.96 | BF17: =IFERROR((AY17-I17)/I17,0) -> 0.098296965 | BG17: =IFERROR((AZ17-J17)/J17,0) -> 1.8122092 | BH17: =IFERROR((BA17-K17)/K17,0) -> 0 | BI17: =IFERROR((BB17-L17)/L17,0) -> 0 | BJ17: =IFERROR((BC17-M17)/M17,0) -> 0 | BK17: =IFERROR((BD17-N17)/N17,0) -> 0.52611274
A18: TikTok CoGS | B18: -18989 | G18: -18989 | I18: 0 | J18: 0 | K18: 0 | L18: 0 | N18: 0 | P18: =IFERROR((I18-B18)/B18,0) -> -1 | Q18: =IFERROR((J18-C18)/C18,0) -> 0 | R18: =IFERROR((K18-D18)/D18,0) -> 0 | S18: =IFERROR((L18-E18)/E18,0) -> 0 | T18: =IFERROR((M18-F18)/F18,0) -> 0 | U18: =IFERROR((N18-G18)/G18,0) -> -1 | W18: 0 | X18: 0 | Y18: 0 | Z18: 0 | AB18: 0 | AD18: =IFERROR((W18-I18)/I18,0) -> 0 | AE18: =IFERROR((X18-J18)/J18,0) -> 0 | AF18: =IFERROR((Y18-K18)/K18,0) -> 0 | AG18: =IFERROR((Z18-L18)/L18,0) -> 0 | AH18: =IFERROR((AA18-M18)/M18,0) -> 0 | AI18: =IFERROR((AB18-N18)/N18,0) -> 0 | AK18: 0 | AL18: 0 | AM18: 0 | AN18: 0 | AP18: 0 | AR18: =IFERROR((AK18-B18)/B18,0) -> -1 | AS18: =IFERROR((AL18-C18)/C18,0) -> 0 | AT18: =IFERROR((AM18-D18)/D18,0) -> 0 | AU18: =IFERROR((AN18-E18)/E18,0) -> 0 | AV18: =IFERROR((AO18-F18)/F18,0) -> 0 | AW18: =IFERROR((AP18-G18)/G18,0) -> -1 | AY18: 0 | AZ18: 0 | BA18: 0 | BB18: 0 | BD18: 0 | BF18: =IFERROR((AY18-I18)/I18,0) -> 0 | BG18: =IFERROR((AZ18-J18)/J18,0) -> 0 | BH18: =IFERROR((BA18-K18)/K18,0) -> 0 | BI18: =IFERROR((BB18-L18)/L18,0) -> 0 | BJ18: =IFERROR((BC18-M18)/M18,0) -> 0 | BK18: =IFERROR((BD18-N18)/N18,0) -> 0
A20: Total CoGS | B20: -1929811 | C20: -790895 | D20: -1505406 | E20: -489293 | F20: 26112 | G20: -4673115 | I20: -2504519.6 | J20: -1126855.9 | K20: -1772414.3 | L20: -309553.05 | N20: -5713342.9 | P20: =IFERROR((I20-B20)/B20,0) -> 0.29780566 | Q20: =IFERROR((J20-C20)/C20,0) -> 0.42478573 | R20: =IFERROR((K20-D20)/D20,0) -> 0.17736634 | S20: =IFERROR((L20-E20)/E20,0) -> -0.36734626 | T20: =IFERROR((M20-F20)/F20,0) -> -1 | U20: =IFERROR((N20-G20)/G20,0) -> 0.22259841 | W20: -3916735.7 | X20: -1847050.7 | Y20: -2034821 | Z20: -319555.41 | AB20: -8118162.7 | AD20: =IFERROR((W20-I20)/I20,0) -> 0.56386701 | AE20: =IFERROR((X20-J20)/J20,0) -> 0.63911876 | AF20: =IFERROR((Y20-K20)/K20,0) -> 0.14805039 | AG20: =IFERROR((Z20-L20)/L20,0) -> 0.032312292 | AH20: =IFERROR((AA20-M20)/M20,0) -> 0 | AI20: =IFERROR((AB20-N20)/N20,0) -> 0.4209129 | AK20: -2732183.7 | AL20: -1347857.9 | AM20: -1797289.6 | AN20: -156274.47 | AP20: -6033605.7 | AR20: =IFERROR((AK20-B20)/B20,0) -> 0.41577788 | AS20: =IFERROR((AL20-C20)/C20,0) -> 0.70421851 | AT20: =IFERROR((AM20-D20)/D20,0) -> 0.19389031 | AU20: =IFERROR((AN20-E20)/E20,0) -> -0.68061169 | AV20: =IFERROR((AO20-F20)/F20,0) -> -1 | AW20: =IFERROR((AP20-G20)/G20,0) -> 0.29113144 | AY20: -3922687.4 | AZ20: -2634446.1 | BA20: -2067744.1 | BB20: -611636.36 | BD20: -9236514 | BF20: =IFERROR((AY20-I20)/I20,0) -> 0.56624342 | BG20: =IFERROR((AZ20-J20)/J20,0) -> 1.3378731 | BH20: =IFERROR((BA20-K20)/K20,0) -> 0.16662568 | BI20: =IFERROR((BB20-L20)/L20,0) -> 0.9758693 | BJ20: =IFERROR((BC20-M20)/M20,0) -> 0 | BK20: =IFERROR((BD20-N20)/N20,0) -> 0.61665667
W21: -0.21230577 | X21: -0.26074804 | Y21: -0.25883441 | Z21: -0.34669453 | AB21: -0.23657478 | AK21: -0.22133245 | AL21: -0.23034196 | AM21: -0.24693231 | AN21: -0.28747353 | AP21: -0.23215809 | AY21: -0.21107566 | AZ21: -0.23111432 | BA21: -0.24657897 | BB21: -0.31100902 | BD21: -0.23418824
A22: DTC CM1 | B22: =B6+B15 -> 1672936 | C22: =C6+C15 -> 872872 | D22: =D6+D15 -> 3680859 | E22: =E6+E15 -> 40175 | F22: =F6+F15 -> 26112 | G22: =G6+G15 -> 6257738 | I22: =I6+I15 -> 3822008.8 | J22: =J6+J15 -> 1266310.7 | K22: =K6+K15 -> 4577339 | L22: =L6+L15 -> 0 | M22: =M6+M15 -> 0 | N22: =N6+N15 -> 9665658.6 | W22: =W6+W15 -> 8886213 | X22: =X6+X15 -> 2647258.7 | Y22: =Y6+Y15 -> 5271408 | Z22: =Z6+Z15 -> 0 | AA22: =AA6+AA15 -> 0 | AB22: =AB6+AB15 -> 16804880 | AK22: 3953884.8 | AL22: 1644210.2 | AM22: 4892521 | AN22: 0 | AP22: 10490616 | AY22: 9076129.8 | AZ22: 3912306.4 | BA22: 5674340.3 | BB22: 0 | BD22: 18662776
A23: B2B CM1 | B23: =B7+B16 -> 2598162 | C23: =C7+C16 -> 838981 | D23: =D7+D16 -> 407302 | E23: =E7+E16 -> 679527 | F23: =F7+F16 -> 0 | G23: =G7+G16 -> 4575458 | I23: =I7+I16 -> 3111849.5 | J23: =J7+J16 -> 1226538.6 | K23: =K7+K16 -> 490408.3 | L23: =L7+L16 -> 481798.04 | M23: =M7+M16 -> 0 | N23: =N7+N16 -> 5310594.4 | W23: =W7+W16 -> 3702602.1 | X23: =X7+X16 -> 1763131.1 | Y23: =Y7+Y16 -> 555248.71 | Z23: =Z7+Z16 -> 498599.98 | AA23: =AA7+AA16 -> 0 | AB23: =AB7+AB16 -> 6519582 | AK23: 3566231.6 | AL23: 1765419.9 | AM23: 588660.38 | AN23: 283773.96 | AP23: 6175408.7 | AY23: 3472582.5 | AZ23: 2933358 | BA23: 643643.4 | BB23: 1251418 | BD23: 7406048.7
A24: Marketplace CM1 | B24: =B8+B17 -> 1834834 | C24: =C8+C17 -> 499090 | D24: =D8+D17 -> 0 | E24: =E8+E17 -> 115330 | F24: =F8+F17 -> 0 | G24: =G8+G17 -> 2450510 | I24: =I8+I17 -> 1923771.5 | J24: =J8+J17 -> 682302.33 | K24: =K8+K17 -> 0 | L24: =L8+L17 -> 103564.98 | M24: =M8+M17 -> 0 | N24: =N8+N17 -> 2709638.8 | W24: =W8+W17 -> 1943009.2 | X24: =X8+X17 -> 826220.34 | Y24: =Y8+Y17 -> 0 | Z24: =Z8+Z17 -> 103564.98 | AA24: =AA8+AA17 -> 0 | AB24: =AB8+AB17 -> 2872794.5 | AK24: 2091952.8 | AL24: 1094063.6 | AM24: 0 | AN24: 103564.98 | AP24: 3289581.4 | AY24: 2112872.4 | AZ24: 1918776.9 | BA24: 0 | BB24: 103564.98 | BD24: 4135214.3
A25: TikTok CM1 | B25: =B9+B18 -> 70883 | C25: =C9+C18 -> 0 | D25: =D9+D18 -> 0 | E25: =E9+E18 -> 0 | F25: =F9+F18 -> 0 | G25: =G9+G18 -> 70883 | I25: =I9+I18 -> 0 | J25: =J9+J18 -> 0 | K25: =K9+K18 -> 0 | L25: =L9+L18 -> 0 | M25: =M9+M18 -> 0 | N25: =N9+N18 -> 0 | W25: =W9+W18 -> 0 | X25: =X9+X18 -> 0 | Y25: =Y9+Y18 -> 0 | Z25: =Z9+Z18 -> 0 | AA25: =AA9+AA18 -> 0 | AB25: =AB9+AB18 -> 0 | AK25: 0 | AL25: 0 | AM25: 0 | AN25: 0 | AP25: 0 | AY25: 0 | AZ25: 0 | BA25: 0 | BB25: 0 | BD25: 0
A26: Total CM1 | B26: =B11+B20 -> 6176814 | C26: =C11+C20 -> 2210943 | D26: =D11+D20 -> 4088162 | E26: =E11+E20 -> 835033 | F26: =F11+F20 -> 26112 | G26: =G11+G20 -> 13354587 | I26: =I11+I20 -> 8857629.8 | J26: =J11+J20 -> 3175151.6 | K26: =K11+K20 -> 5067747.3 | L26: =L11+L20 -> 585363.02 | M26: =M11+M20 -> 0 | N26: =N11+N20 -> 17685892 | W26: =W11+W20 -> 14531824 | X26: =X11+X20 -> 5236610.2 | Y26: =Y11+Y20 -> 5826656.7 | Z26: =Z11+Z20 -> 602164.97 | AA26: =AA11+AA20 -> 0 | AB26: =AB11+AB20 -> 26197256 | AK26: 9612069.3 | AL26: 4503693.8 | AM26: 5481181.3 | AN26: 387338.95 | AP26: 19955606 | AY26: 14661585 | AZ26: 8764441.3 | BA26: 6317983.7 | BB26: 1354983 | BD26: 30204039
A28: DTC CM1% | B28: =IFERROR(B22/B6,0) -> 0.75946025 | C28: =IFERROR(C22/C6,0) -> 0.75710333 | D28: =IFERROR(D22/D6,0) -> 0.74350108 | E28: =IFERROR(E22/E6,0) -> 0.86216147 | F28: =IFERROR(F22/F6,0) -> 0 | G28: =IFERROR(G22/G6,0) -> 0.7491592 | I28: =IFERROR(I22/I6,0) -> 0.79 | J28: =IFERROR(J22/J6,0) -> 0.76 | K28: =IFERROR(K22/K6,0) -> 0.76 | L28: =IFERROR(L22/L6,0) -> 0 | M28: =IFERROR(M22/M6,0) -> 0 | N28: =IFERROR(N22/N6,0) -> 0.77158614 | W28: =IFERROR(W22/W6,0) -> 0.8 | X28: =IFERROR(X22/X6,0) -> 0.76 | Y28: =IFERROR(Y22/Y6,0) -> 0.76 | Z28: =IFERROR(Z22/Z6,0) -> 0 | AA28: =IFERROR(AA22/AA6,0) -> 0 | AB28: =IFERROR(AB22/AB6,0) -> 0.78063963 | AK28: 0.79 | AL28: 0.76 | AM28: 0.76 | AN28: 0 | AP28: 0.77103549 | AY28: 0.8 | AZ28: 0.76 | BA28: 0.76 | BB28: 0 | BD28: 0.77894083
A29: B2B CM1% | B29: =IFERROR(B23/B7,0) -> 0.72234934 | C29: =IFERROR(C23/C7,0) -> 0.67496406 | D29: =IFERROR(D23/D7,0) -> 0.63358103 | E29: =IFERROR(E23/E7,0) -> 0.59285669 | F29: =IFERROR(F23/F7,0) -> 0 | G29: =IFERROR(G23/G7,0) -> 0.69022229 | I29: =IFERROR(I23/I7,0) -> 0.7448 | J29: =IFERROR(J23/J7,0) -> 0.68 | K29: =IFERROR(K23/K7,0) -> 0.6 | L29: =IFERROR(L23/L7,0) -> 0.62683735 | M29: =IFERROR(M23/M7,0) -> 0 | N29: =IFERROR(N23/N7,0) -> 0.7017357 | W29: =IFERROR(W23/W7,0) -> 0.7448 | X29: =IFERROR(X23/X7,0) -> 0.68 | Y29: =IFERROR(Y23/Y7,0) -> 0.6 | Z29: =IFERROR(Z23/Z7,0) -> 0.62683735 | AA29: =IFERROR(AA23/AA7,0) -> 0 | AB29: =IFERROR(AB23/AB7,0) -> 0.7021669 | AK29: 0.7448 | AL29: 0.75 | AM29: 0.7 | AN29: 0.68 | AP29: 0.73765751 | AY29: 0.7448 | AZ29: 0.75 | BA29: 0.7 | BB29: 0.68 | BD29: 0.70949778
A30: Marketplace CM1% | B30: =IFERROR(B24/B8,0) -> 0.82756944 | C30: =IFERROR(C24/C8,0) -> 0.82368144 | D30: =IFERROR(D24/D8,0) -> 0 | E30: =IFERROR(E24/E8,0) -> 0.87678752 | F30: =IFERROR(F24/F8,0) -> 0 | G30: =IFERROR(G24/G8,0) -> 0.82903649 | I30: =IFERROR(I24/I8,0) -> 0.82 | J30: =IFERROR(J24/J8,0) -> 0.82 | K30: =IFERROR(K24/K8,0) -> 0 | L30: =IFERROR(L24/L8,0) -> 0.82 | M30: =IFERROR(M24/M8,0) -> 0 | N30: =IFERROR(N24/N8,0) -> 0.82 | W30: =IFERROR(W24/W8,0) -> 0.82 | X30: =IFERROR(X24/X8,0) -> 0.82 | Y30: =IFERROR(Y24/Y8,0) -> 0 | Z30: =IFERROR(Z24/Z8,0) -> 0.82 | AA30: =IFERROR(AA24/AA8,0) -> 0 | AB30: =IFERROR(AB24/AB8,0) -> 0.82 | AK30: 0.82 | AL30: 0.82 | AM30: 0 | AN30: 0.82 | AP30: 0.82 | AY30: 0.82 | AZ30: 0.82 | BA30: 0 | BB30: 0.82 | BD30: 0.82
A31: TikTok CM1% | B31: =IFERROR(B25/B9,0) -> 0.78871061 | C31: =IFERROR(C25/C9,0) -> 0 | D31: =IFERROR(D25/D9,0) -> 0 | E31: =IFERROR(E25/E9,0) -> 0 | F31: =IFERROR(F25/F9,0) -> 0 | G31: =IFERROR(G25/G9,0) -> 0.78871061 | I31: =IFERROR(I25/I9,0) -> 0 | J31: =IFERROR(J25/J9,0) -> 0 | K31: =IFERROR(K25/K9,0) -> 0 | L31: =IFERROR(L25/L9,0) -> 0 | M31: =IFERROR(M25/M9,0) -> 0 | N31: =IFERROR(N25/N9,0) -> 0 | W31: =IFERROR(W25/W9,0) -> 0 | X31: =IFERROR(X25/X9,0) -> 0 | Y31: =IFERROR(Y25/Y9,0) -> 0 | Z31: =IFERROR(Z25/Z9,0) -> 0 | AA31: =IFERROR(AA25/AA9,0) -> 0 | AB31: =IFERROR(AB25/AB9,0) -> 0 | AK31: 0 | AL31: 0 | AM31: 0 | AN31: 0 | AP31: 0 | AY31: 0 | AZ31: 0 | BA31: 0 | BB31: 0 | BD31: 0
A32: Total CM1% | B32: =IFERROR(B26/B11,0) -> 0.76194643 | C32: =IFERROR(C26/C10,0) -> 0 | D32: =IFERROR(D26/D10,0) -> 0 | E32: =IFERROR(E26/E10,0) -> 0 | F32: =IFERROR(F26/F10,0) -> 0 | G32: =IFERROR(G26/G10,0) -> 0 | I32: =IFERROR(I26/I11,0) -> 0.77957343 | J32: =IFERROR(J26/J10,0) -> 0 | K32: =IFERROR(K26/K10,0) -> 0 | L32: =IFERROR(L26/L10,0) -> 0 | M32: =IFERROR(M26/M10,0) -> 0 | N32: =IFERROR(N26/N10,0) -> 0 | W32: =IFERROR(W26/W11,0) -> 0.78769423 | X32: =IFERROR(X26/X10,0) -> 0 | Y32: =IFERROR(Y26/Y10,0) -> 0 | Z32: =IFERROR(Z26/Z10,0) -> 0 | AA32: =IFERROR(AA26/AA10,0) -> 0 | AB32: =IFERROR(AB26/AB10,0) -> 0 | AK32: 0.77866755 | AL32: 0.76965804 | AM32: 0.75306769 | AN32: 0.71252647 | AP32: 0.76784191 | AY32: 0.78892434 | AZ32: 0.76888568 | BA32: 0.75342103 | BB32: 0.68899098 | BD32: 0.76581176
A34: Fulfilment
A36: Central | B36: -8901 | C36: 14198 | D36: - | E36: -128 | F36: -340393 | G36: -350589 | I36: 0 | J36: 0 | K36: 0 | L36: 0 | N36: -300000 | P36: =IFERROR((I36-B36)/B36,0) -> -1 | Q36: =IFERROR((J36-C36)/C36,0) -> -1 | R36: =IFERROR((K36-D36)/D36,0) -> 0 | S36: =IFERROR((L36-E36)/E36,0) -> -1 | T36: =IFERROR((M36-F36)/F36,0) -> -1 | U36: =IFERROR((N36-G36)/G36,0) -> -0.14429717 | W36: 0 | X36: 0 | Y36: 0 | Z36: 0 | AB36: -300000 | AD36: =IFERROR((W36-I36)/I36,0) -> 0 | AE36: =IFERROR((X36-J36)/J36,0) -> 0 | AF36: =IFERROR((Y36-K36)/K36,0) -> 0 | AG36: =IFERROR((Z36-L36)/L36,0) -> 0 | AH36: =IFERROR((AA36-M36)/M36,0) -> 0 | AI36: =IFERROR((AB36-N36)/N36,0) -> 0 | AK36: 0 | AL36: 0 | AM36: 0 | AN36: 0 | AP36: -300000 | AR36: =IFERROR((AK36-B36)/B36,0) -> -1 | AS36: =IFERROR((AL36-C36)/C36,0) -> -1 | AT36: =IFERROR((AM36-D36)/D36,0) -> 0 | AU36: =IFERROR((AN36-E36)/E36,0) -> -1 | AV36: =IFERROR((AO36-F36)/F36,0) -> -1 | AW36: =IFERROR((AP36-G36)/G36,0) -> -0.14429717 | AY36: 0 | AZ36: 0 | BA36: 0 | BB36: 0 | BD36: -300000 | BF36: =IFERROR((AY36-I36)/I36,0) -> 0 | BG36: =IFERROR((AZ36-J36)/J36,0) -> 0 | BH36: =IFERROR((BA36-K36)/K36,0) -> 0 | BI36: =IFERROR((BB36-L36)/L36,0) -> 0 | BJ36: =IFERROR((BC36-M36)/M36,0) -> 0 | BK36: =IFERROR((BD36-N36)/N36,0) -> 0
A37: DTC Fulfilment | B37: -263146 | C37: -242539 | D37: -833420 | E37: -27005 | F37: -42154 | G37: -1407620 | I37: -660990.96 | J37: -322094.41 | K37: -1164276.1 | L37: 0 | M37: -300000 | N37: -2147361.5 | P37: =IFERROR((I37-B37)/B37,0) -> 1.5118792 | Q37: =IFERROR((J37-C37)/C37,0) -> 0.32801081 | R37: =IFERROR((K37-D37)/D37,0) -> 0.39698606 | S37: =IFERROR((L37-E37)/E37,0) -> -1 | T37: =IFERROR((M37-F37)/F37,0) -> 6.1167623 | U37: =IFERROR((N37-G37)/G37,0) -> 0.52552642 | W37: -1517601.2 | X37: -673347.58 | Y37: -1340817.1 | Z37: 0 | AA37: -300000 | AB37: -3531765.9 | AD37: =IFERROR((W37-I37)/I37,0) -> 1.2959485 | AE37: =IFERROR((X37-J37)/J37,0) -> 1.0905286 | AF37: =IFERROR((Y37-K37)/K37,0) -> 0.15163155 | AG37: =IFERROR((Z37-L37)/L37,0) -> 0 | AH37: =IFERROR((AA37-M37)/M37,0) -> 0 | AI37: =IFERROR((AB37-N37)/N37,0) -> 0.64470021 | AK37: -683798.04 | AL37: -418215.63 | AM37: -1244444.7 | AN37: 0 | AO37: -300000 | AP37: -2346458.4 | AR37: =IFERROR((AK37-B37)/B37,0) -> 1.59855 | AS37: =IFERROR((AL37-C37)/C37,0) -> 0.72432321 | AT37: =IFERROR((AM37-D37)/D37,0) -> 0.49317836 | AU37: =IFERROR((AN37-E37)/E37,0) -> -1 | AV37: =IFERROR((AO37-F37)/F37,0) -> 6.1167623 | AW37: =IFERROR((AP37-G37)/G37,0) -> 0.66696863 | AY37: -1550035.5 | AZ37: -995120.72 | BA37: -1443305.6 | BB37: 0 | BC37: -300000 | BD37: -3988461.8 | BF37: =IFERROR((AY37-I37)/I37,0) -> 1.3450177 | BG37: =IFERROR((AZ37-J37)/J37,0) -> 2.0895311 | BH37: =IFERROR((BA37-K37)/K37,0) -> 0.23965916 | BI37: =IFERROR((BB37-L37)/L37,0) -> 0 | BJ37: =IFERROR((BC37-M37)/M37,0) -> 0 | BK37: =IFERROR((BD37-N37)/N37,0) -> 0.85737789
A38: B2B Fulfilment | B38: -203593 | C38: -94006 | D38: -36834 | E38: -77593 | F38: 5673 | G38: -406351 | I38: -217872.6 | J38: -125712.74 | K38: -49040.83 | L38: 0 | N38: -392626.17 | P38: =IFERROR((I38-B38)/B38,0) -> 0.070137967 | Q38: =IFERROR((J38-C38)/C38,0) -> 0.33728425 | R38: =IFERROR((K38-D38)/D38,0) -> 0.33140115 | S38: =IFERROR((L38-E38)/E38,0) -> -1 | T38: =IFERROR((M38-F38)/F38,0) -> -1 | U38: =IFERROR((N38-G38)/G38,0) -> -0.033775793 | W38: -259233.47 | X38: -180710.21 | Y38: -55524.871 | Z38: -110065.2 | AB38: -605533.76 | AD38: =IFERROR((W38-I38)/I38,0) -> 0.18983973 | AE38: =IFERROR((X38-J38)/J38,0) -> 0.43748525 | AF38: =IFERROR((Y38-K38)/K38,0) -> 0.13221721 | AG38: =IFERROR((Z38-L38)/L38,0) -> 0 | AH38: =IFERROR((AA38-M38)/M38,0) -> 0 | AI38: =IFERROR((AB38-N38)/N38,0) -> 0.5422654 | AK38: -249685.65 | AL38: -164056.62 | AM38: -50456.604 | AN38: -29673.807 | AP38: -493872.68 | AR38: =IFERROR((AK38-B38)/B38,0) -> 0.22639604 | AS38: =IFERROR((AL38-C38)/C38,0) -> 0.74517181 | AT38: =IFERROR((AM38-D38)/D38,0) -> 0.36983775 | AU38: =IFERROR((AN38-E38)/E38,0) -> -0.61757108 | AV38: =IFERROR((AO38-F38)/F38,0) -> -1 | AW38: =IFERROR((AP38-G38)/G38,0) -> 0.21538444 | AY38: -243128.91 | AZ38: -272590.55 | BA38: -55169.434 | BB38: -184032.06 | BD38: -754920.96 | BF38: =IFERROR((AY38-I38)/I38,0) -> 0.11592238 | BG38: =IFERROR((AZ38-J38)/J38,0) -> 1.1683606 | BH38: =IFERROR((BA38-K38)/K38,0) -> 0.12496942 | BI38: =IFERROR((BB38-L38)/L38,0) -> 0 | BJ38: =IFERROR((BC38-M38)/M38,0) -> 0 | BK38: =IFERROR((BD38-N38)/N38,0) -> 0.92274741
A39: Marketplace Fulfilment | B39: -900844 | C39: -234691 | D39: - | E39: -76999 | F39: -176 | G39: -1213145 | I39: -955288.1 | J39: -360868.49 | K39: 0 | L39: -54308.467 | N39: -1370465.1 | P39: =IFERROR((I39-B39)/B39,0) -> 0.060436773 | Q39: =IFERROR((J39-C39)/C39,0) -> 0.53763243 | R39: =IFERROR((K39-D39)/D39,0) -> 0 | S39: =IFERROR((L39-E39)/E39,0) -> -0.29468608 | T39: =IFERROR((M39-F39)/F39,0) -> -1 | U39: =IFERROR((N39-G39)/G39,0) -> 0.12967952 | W39: -964840.99 | X39: -436986.47 | Y39: 0 | Z39: -54308.467 | AB39: -1456135.9 | AD39: =IFERROR((W39-I39)/I39,0) -> 0.01 | AE39: =IFERROR((X39-J39)/J39,0) -> 0.21092997 | AF39: =IFERROR((Y39-K39)/K39,0) -> 0 | AG39: =IFERROR((Z39-L39)/L39,0) -> 0 | AH39: =IFERROR((AA39-M39)/M39,0) -> 0 | AI39: =IFERROR((AB39-N39)/N39,0) -> 0.062512254 | AK39: -1038802 | AL39: -578648.3 | AM39: 0 | AN39: -54308.467 | AP39: -1671758.8 | AR39: =IFERROR((AK39-B39)/B39,0) -> 0.15314306 | AS39: =IFERROR((AL39-C39)/C39,0) -> 1.4655752 | AT39: =IFERROR((AM39-D39)/D39,0) -> 0 | AU39: =IFERROR((AN39-E39)/E39,0) -> -0.29468608 | AV39: =IFERROR((AO39-F39)/F39,0) -> -1 | AW39: =IFERROR((AP39-G39)/G39,0) -> 0.37803707 | AY39: -1049190 | AZ39: -1014837.7 | BA39: 0 | BB39: -54308.467 | BD39: -2118336.2 | BF39: =IFERROR((AY39-I39)/I39,0) -> 0.098296965 | BG39: =IFERROR((AZ39-J39)/J39,0) -> 1.8122092 | BH39: =IFERROR((BA39-K39)/K39,0) -> 0 | BI39: =IFERROR((BB39-L39)/L39,0) -> 0 | BJ39: =IFERROR((BC39-M39)/M39,0) -> 0 | BK39: =IFERROR((BD39-N39)/N39,0) -> 0.54570609
A40: TikTok Fulfilment | B40: -27114 | C40: -1531 | D40: -6 | E40: -87 | F40: -526 | G40: -29264 | I40: 0 | J40: 0 | K40: 0 | L40: 0 | N40: 0 | P40: =IFERROR((I40-B40)/B40,0) -> -1 | Q40: =IFERROR((J40-C40)/C40,0) -> -1 | R40: =IFERROR((K40-D40)/D40,0) -> -1 | S40: =IFERROR((L40-E40)/E40,0) -> -1 | T40: =IFERROR((M40-F40)/F40,0) -> -1 | U40: =IFERROR((N40-G40)/G40,0) -> -1 | W40: 0 | X40: 0 | Y40: 0 | Z40: 0 | AB40: 0 | AD40: =IFERROR((W40-I40)/I40,0) -> 0 | AE40: =IFERROR((X40-J40)/J40,0) -> 0 | AF40: =IFERROR((Y40-K40)/K40,0) -> 0 | AG40: =IFERROR((Z40-L40)/L40,0) -> 0 | AH40: =IFERROR((AA40-M40)/M40,0) -> 0 | AI40: =IFERROR((AB40-N40)/N40,0) -> 0 | AK40: 0 | AL40: 0 | AM40: 0 | AN40: 0 | AP40: 0 | AR40: =IFERROR((AK40-B40)/B40,0) -> -1 | AS40: =IFERROR((AL40-C40)/C40,0) -> -1 | AT40: =IFERROR((AM40-D40)/D40,0) -> -1 | AU40: =IFERROR((AN40-E40)/E40,0) -> -1 | AV40: =IFERROR((AO40-F40)/F40,0) -> -1 | AW40: =IFERROR((AP40-G40)/G40,0) -> -1 | AY40: 0 | AZ40: 0 | BA40: 0 | BB40: 0 | BD40: 0 | BF40: =IFERROR((AY40-I40)/I40,0) -> 0 | BG40: =IFERROR((AZ40-J40)/J40,0) -> 0 | BH40: =IFERROR((BA40-K40)/K40,0) -> 0 | BI40: =IFERROR((BB40-L40)/L40,0) -> 0 | BJ40: =IFERROR((BC40-M40)/M40,0) -> 0 | BK40: =IFERROR((BD40-N40)/N40,0) -> 0
A42: Total Fulfilment | B42: =SUM(B36:B41) -> -1403598 | C42: =SUM(C36:C41) -> -558569 | D42: =SUM(D36:D41) -> -870260 | E42: =SUM(E36:E41) -> -181812 | F42: =SUM(F36:F41) -> -377576 | G42: =SUM(G36:G41) -> -3406969 | I42: -1834151.7 | J42: -808675.65 | K42: -1213317 | L42: -54308.467 | M42: -300000 | N42: -4210452.7 | W42: -2741675.7 | X42: -1291044.3 | Y42: -1396342 | Z42: -164373.67 | AA42: -300000 | AB42: -5893435.6 | AD42: =IFERROR((W42-I42)/I42,0) -> 0.49479223 | AE42: =IFERROR((X42-J42)/J42,0) -> 0.59649207 | AF42: =IFERROR((Y42-K42)/K42,0) -> 0.15084684 | AG42: =IFERROR((Z42-L42)/L42,0) -> 2.0266674 | AH42: =IFERROR((AA42-M42)/M42,0) -> 0 | AI42: =IFERROR((AB42-N42)/N42,0) -> 0.39971541 | AK42: -1972285.7 | AL42: -1160920.6 | AM42: -1294901.3 | AN42: -83982.274 | AO42: -300000 | AP42: -4812089.8 | AR42: =IFERROR((AK42-B42)/B42,0) -> 0.40516423 | AS42: =IFERROR((AL42-C42)/C42,0) -> 1.0783834 | AT42: =IFERROR((AM42-D42)/D42,0) -> 0.48794764 | AU42: =IFERROR((AN42-E42)/E42,0) -> -0.53808179 | AV42: =IFERROR((AO42-F42)/F42,0) -> -0.20545797 | AW42: =IFERROR((AP42-G42)/G42,0) -> 0.41242548 | AY42: -2842354.4 | AZ42: -2282549 | BA42: -1498475 | BB42: -238340.52 | BC42: -300000 | BD42: -7161718.9 | BF42: =IFERROR((AY42-I42)/I42,0) -> 0.54968342 | BG42: =IFERROR((AZ42-J42)/J42,0) -> 1.8225766 | BH42: =IFERROR((BA42-K42)/K42,0) -> 0.23502354 | BI42: =IFERROR((BB42-L42)/L42,0) -> 3.388644 | BJ42: =IFERROR((BC42-M42)/M42,0) -> 0 | BK42: =IFERROR((BD42-N42)/N42,0) -> 0.70093797
